<?xml version="1.0" ?>
<!-- =================================================================================== -->
<!-- |    This document was autogenerated by xacro from minnav_moma_j2s6s200_xacro.xacro | -->
<!-- |    EDITING THIS FILE BY HAND IS NOT RECOMMENDED                                 | -->
<!-- =================================================================================== -->
<robot name="minnav_kinova_xacro" xmlns:body="http://playerstage.sourceforge.net/gazebo/xmlschema/#body" xmlns:controller="http://playerstage.sourceforge.net/gazebo/xmlschema/#controller" xmlns:gazebo="http://playerstage.sourceforge.net/gazebo/xmlschema/#gz" xmlns:geom="http://playerstage.sourceforge.net/gazebo/xmlschema/#geom" xmlns:interface="http://playerstage.sourceforge.net/gazebo/xmlschema/#interface" xmlns:joint="http://playerstage.sourceforge.net/gazebo/xmlschema/#joint" xmlns:model="http://playerstage.sourceforge.net/gazebo/xmlschema/#model" xmlns:physics="http://playerstage.sourceforge.net/gazebo/xmlschema/#physics" xmlns:renderable="http://playerstage.sourceforge.net/gazebo/xmlschema/#renderable" xmlns:rendering="http://playerstage.sourceforge.net/gazebo/xmlschema/#rendering" xmlns:sensor="http://playerstage.sourceforge.net/gazebo/xmlschema/#sensor" xmlns:xi="http://www.w3.org/2001/XInclude">
  <!-- This URDF was automatically created by SolidWorks to URDF Exporter! Originally created by Stephen Brawner (brawner@gmail.com) 
     Commit Version: 1.5.1-0-g916b5db  Build Version: 1.5.7152.31018
     For more information, please see http://wiki.ros.org/sw_urdf_exporter -->
  <!-- we add a base footprint link as the root link, do not include inertia param tag-->
  <link name="base_footprint">
    <origin rpy="0 0 0" xyz="0 0 0"/>
  </link>
  <joint name="base_link_joint" type="fixed">
    <origin rpy="0 0 0" xyz="0 0 0.0"/>
    <parent link="base_footprint"/>
    <child link="moma_base_link"/>
  </joint>
  <link name="moma_base_link">
    <inertial>
      <origin rpy="0 0 0" xyz="-0.0697248975605124 9.35986032828009E-05 0.186131310444443"/>
      <mass value="64.9999523677222"/>
      <inertia ixx="1.35069488959022" ixy="0.000479754719690234" ixz="1.48197273533961E-06" iyy="0.963094057696194" iyz="-7.03349014736132E-06" izz="1.34062606564175"/>
    </inertial>
    <visual>
      <origin rpy="0 0 0" xyz="0 0 0"/>
      <geometry>
        <mesh filename="package://minnav_moma_description/meshes/v3/moma_base_link.STL"/>
      </geometry>
      <material name="">
        <color rgba="0.752941176470588 0.752941176470588 0.752941176470588 1"/>
      </material>
    </visual>
    <collision>
      <origin rpy="0 0 0" xyz="0 0 0"/>
      <geometry>
        <mesh filename="package://minnav_moma_description/meshes/v3/moma_base_link.STL"/>
      </geometry>
    </collision>
  </link>
  <link name="ArmBase">
    <inertial>
      <origin rpy="0 0 0" xyz="-0.0272741114005057 0.00094394189111098 -0.0308551972687778"/>
      <mass value="0.713162476928904"/>
      <inertia ixx="0.00220534830451126" ixy="8.35547600892114E-07" ixz="-6.18305224606399E-05" iyy="0.00152386550417795" iyz="1.06604349141974E-06" izz="0.000996301117911694"/>
    </inertial>
    <visual>
      <origin rpy="0 0 0" xyz="0 0 0"/>
      <geometry>
        <mesh filename="package://minnav_moma_description/meshes/v3/ArmBase.STL"/>
      </geometry>
      <material name="">
        <color rgba="0.752941176470588 0.752941176470588 0.752941176470588 1"/>
      </material>
    </visual>
    <collision>
      <origin rpy="0 0 0" xyz="0 0 0"/>
      <geometry>
        <mesh filename="package://minnav_moma_description/meshes/v3/ArmBase.STL"/>
      </geometry>
    </collision>
  </link>
  <joint name="JT_ArmBase" type="prismatic">
    <origin rpy="0 0 0" xyz="0.034 -0.001 0.3335"/>
    <parent link="moma_base_link"/>
    <child link="ArmBase"/>
    <axis xyz="0 0 1"/>
    <limit effort="0" lower="0" upper="0.49" velocity="0"/>
  </joint>
  <link name="LIDAR">
    <inertial>
      <origin rpy="0 0 0" xyz="8.22216969754708E-05 0.0195154420160331 3.427162408858E-09"/>
      <mass value="0.102883853456169"/>
      <inertia ixx="3.66225482144748E-05" ixy="1.0587412031796E-07" ixz="-3.58548249909878E-12" iyy="4.69758377443588E-05" iyz="-6.02604694180553E-13" izz="3.69805831442243E-05"/>
    </inertial>
    <visual>
      <origin rpy="0 0 0" xyz="0 0 0"/>
      <geometry>
        <mesh filename="package://minnav_moma_description/meshes/v3/LIDAR.STL"/>
      </geometry>
      <material name="">
        <color rgba="0.752941176470588 0.752941176470588 0.752941176470588 1"/>
      </material>
    </visual>
    <collision>
      <origin rpy="0 0 0" xyz="0 0 0"/>
      <geometry>
        <mesh filename="package://minnav_moma_description/meshes/v3/LIDAR.STL"/>
      </geometry>
    </collision>
  </link>
  <joint name="JT_LIDAR" type="fixed">
    <origin rpy="1.5708 0 3.1416" xyz="0.213 0 0.0905"/>
    <parent link="moma_base_link"/>
    <child link="LIDAR"/>
    <axis xyz="0 0 0"/>
  </joint>
  <link name="Pantilt_PanLink">
    <inertial>
      <origin rpy="0 0 0" xyz="2.18543483591707E-12 9.36750677027476E-17 0.022419493625198"/>
      <mass value="0.125638006386443"/>
      <inertia ixx="5.7984036976015E-05" ixy="-4.95095367264507E-09" ixz="1.26449088862416E-16" iyy="0.000158965664023198" iyz="9.95930618769165E-20" izz="0.000150893790612493"/>
    </inertial>
    <visual>
      <origin rpy="0 0 0" xyz="0 0 0"/>
      <geometry>
        <mesh filename="package://minnav_moma_description/meshes/v3/Pantilt_PanLink.STL"/>
      </geometry>
      <material name="">
        <color rgba="0.796078431372549 0.823529411764706 0.937254901960784 1"/>
      </material>
    </visual>
    <collision>
      <origin rpy="0 0 0" xyz="0 0 0"/>
      <geometry>
        <mesh filename="package://minnav_moma_description/meshes/v3/Pantilt_PanLink.STL"/>
      </geometry>
    </collision>
  </link>
  <joint name="JT_Pantilt_PanLink" type="continuous">
    <origin rpy="0 0 -1.5708" xyz="-0.021 0 1.0081"/>
    <parent link="moma_base_link"/>
    <child link="Pantilt_PanLink"/>
    <axis xyz="0 0 1"/>
  </joint>
  <link name="Pantilt_TiltLink">
    <inertial>
      <origin rpy="0 0 0" xyz="-2.25379299249759E-12 0.031479884333478 1.20049803431499E-13"/>
      <mass value="0.119003363420873"/>
      <inertia ixx="7.90464190146043E-05" ixy="-3.79029998872968E-16" ixz="7.60779981349867E-19" iyy="0.00035798448028944" iyz="2.37471710121675E-16" izz="0.00028284413383159"/>
    </inertial>
    <visual>
      <origin rpy="0 0 0" xyz="0 0 0"/>
      <geometry>
        <mesh filename="package://minnav_moma_description/meshes/v3/Pantilt_TiltLink.STL"/>
      </geometry>
      <material name="">
        <color rgba="0.796078431372549 0.823529411764706 0.937254901960784 1"/>
      </material>
    </visual>
    <collision>
      <origin rpy="0 0 0" xyz="0 0 0"/>
      <geometry>
        <mesh filename="package://minnav_moma_description/meshes/v3/Pantilt_TiltLink.STL"/>
      </geometry>
    </collision>
  </link>
  <joint name="JT_Pantilt_TiltLink" type="continuous">
    <origin rpy="1.5708 0 3.1416" xyz="0 0.00025 0.0413"/>
    <parent link="Pantilt_PanLink"/>
    <child link="Pantilt_TiltLink"/>
    <axis xyz="1 0 0"/>
  </joint>
  <link name="Head">
    <inertial>
      <origin rpy="0 0 0" xyz="7.01161821037004E-06 -0.00244242053568144 -0.0752179075942135"/>
      <mass value="0.398951454797707"/>
      <inertia ixx="0.000860013559453623" ixy="-2.53668430914557E-08" ixz="1.00973665605483E-07" iyy="0.0018274751159565" iyz="5.23242580668497E-06" izz="0.0012846248952368"/>
    </inertial>
    <visual>
      <origin rpy="0 0 0" xyz="0 0 0"/>
      <geometry>
        <mesh filename="package://minnav_moma_description/meshes/v3/Head.STL"/>
      </geometry>
      <material name="">
        <color rgba="0.752941176470588 0.752941176470588 0.752941176470588 1"/>
      </material>
    </visual>
    <collision>
      <origin rpy="0 0 0" xyz="0 0 0"/>
      <geometry>
        <mesh filename="package://minnav_moma_description/meshes/v3/Head.STL"/>
      </geometry>
    </collision>
  </link>
  <joint name="JT_Head" type="fixed">
    <origin rpy="0 0 0" xyz="0 0.0705 0.0795"/>
    <parent link="Pantilt_TiltLink"/>
    <child link="Head"/>
    <axis xyz="0 0 0"/>
  </joint>
  <link name="UniwheelPivot_LF">
    <inertial>
      <origin rpy="0 0 0" xyz="-9.15933995315754E-16 0.0182260960322876 -0.0642291000155078"/>
      <mass value="0.0847351495375798"/>
      <inertia ixx="6.07135705376024E-05" ixy="1.38064990757287E-18" ixz="-6.23412902781099E-19" iyy="3.49474283390521E-05" iyz="1.16340041790674E-05" izz="3.34756139191197E-05"/>
    </inertial>
    <visual>
      <origin rpy="0 0 0" xyz="0 0 0"/>
      <geometry>
        <mesh filename="package://minnav_moma_description/meshes/v3/UniwheelPivot_LF.STL"/>
      </geometry>
      <material name="">
        <color rgba="0.752941176470588 0.752941176470588 0.752941176470588 1"/>
      </material>
    </visual>
    <collision>
      <origin rpy="0 0 0" xyz="0 0 0"/>
      <geometry>
        <mesh filename="package://minnav_moma_description/meshes/v3/UniwheelPivot_LF.STL"/>
      </geometry>
    </collision>
  </link>
  <joint name="JT_UniwheelPivot_LF" type="continuous">
    <origin rpy="0 0 1.5708" xyz="0.2 0.1435 0.031"/>
    <parent link="moma_base_link"/>
    <child link="UniwheelPivot_LF"/>
    <axis xyz="0 0 1"/>
  </joint>
  <link name="UniWheel_LF">
    <inertial>
      <origin rpy="0 0 0" xyz="3.81426298323717E-08 -2.14332611103707E-08 -1.63217898571655E-08"/>
      <mass value="0.131455385710739"/>
      <inertia ixx="4.67614248550029E-05" ixy="2.92736299371043E-11" ixz="-4.25507933450125E-11" iyy="8.85134139088376E-05" iyz="-1.15416488880503E-11" izz="4.6763063659093E-05"/>
    </inertial>
    <visual>
      <origin rpy="0 0 0" xyz="0 0 0"/>
      <geometry>
        <mesh filename="package://minnav_moma_description/meshes/v3/UniWheel_LF.STL"/>
      </geometry>
      <material name="">
        <color rgba="0.752941176470588 0.752941176470588 0.752941176470588 1"/>
      </material>
    </visual>
    <collision>
      <origin rpy="0 0 0" xyz="0 0 0"/>
      <geometry>
        <mesh filename="package://minnav_moma_description/meshes/v3/UniWheel_LF.STL"/>
      </geometry>
    </collision>
  </link>
  <joint name="JT_UniWheel_LF" type="continuous">
    <origin rpy="0 -0.11262 1.5708" xyz="0 0.024 -0.0775"/>
    <parent link="UniwheelPivot_LF"/>
    <child link="UniWheel_LF"/>
    <axis xyz="0 1 0"/>
  </joint>
  <link name="UniwheelPivot_RB">
    <inertial>
      <origin rpy="0 0 0" xyz="-9.71445146547012E-16 0.0182260960322876 -0.0642291000155078"/>
      <mass value="0.0847351495375797"/>
      <inertia ixx="6.07135705376023E-05" ixy="1.38866328531335E-18" ixz="-6.29343822979503E-19" iyy="3.4947428339052E-05" iyz="1.16340041790674E-05" izz="3.34756139191196E-05"/>
    </inertial>
    <visual>
      <origin rpy="0 0 0" xyz="0 0 0"/>
      <geometry>
        <mesh filename="package://minnav_moma_description/meshes/v3/UniwheelPivot_RB.STL"/>
      </geometry>
      <material name="">
        <color rgba="0.752941176470588 0.752941176470588 0.752941176470588 1"/>
      </material>
    </visual>
    <collision>
      <origin rpy="0 0 0" xyz="0 0 0"/>
      <geometry>
        <mesh filename="package://minnav_moma_description/meshes/v3/UniwheelPivot_RB.STL"/>
      </geometry>
    </collision>
  </link>
  <joint name="JT_UniwheelPivot_RB" type="continuous">
    <origin rpy="0 0 1.5708" xyz="-0.2 -0.1435 0.031"/>
    <parent link="moma_base_link"/>
    <child link="UniwheelPivot_RB"/>
    <axis xyz="0 0 1"/>
  </joint>
  <link name="Uniwheel_RB">
    <inertial>
      <origin rpy="0 0 0" xyz="3.8142629943394E-08 -2.14332609993484E-08 -1.63217898641044E-08"/>
      <mass value="0.131455385710739"/>
      <inertia ixx="4.67614248550025E-05" ixy="2.92736298794068E-11" ixz="-4.25507933484007E-11" iyy="8.85134139088377E-05" iyz="-1.15416488244326E-11" izz="4.67630636590926E-05"/>
    </inertial>
    <visual>
      <origin rpy="0 0 0" xyz="0 0 0"/>
      <geometry>
        <mesh filename="package://minnav_moma_description/meshes/v3/Uniwheel_RB.STL"/>
      </geometry>
      <material name="">
        <color rgba="0.752941176470588 0.752941176470588 0.752941176470588 1"/>
      </material>
    </visual>
    <collision>
      <origin rpy="0 0 0" xyz="0 0 0"/>
      <geometry>
        <mesh filename="package://minnav_moma_description/meshes/v3/Uniwheel_RB.STL"/>
      </geometry>
    </collision>
  </link>
  <joint name="JT_Uniwheel_RB" type="continuous">
    <origin rpy="0 -0.11262 1.5708" xyz="0 0.024 -0.0775"/>
    <parent link="UniwheelPivot_RB"/>
    <child link="Uniwheel_RB"/>
    <axis xyz="0 1 0"/>
  </joint>
  <link name="UniwheelPivot_RF">
    <inertial>
      <origin rpy="0 0 0" xyz="-9.15933995315754E-16 0.0182260960322876 -0.0642291000155078"/>
      <mass value="0.0847351495375797"/>
      <inertia ixx="6.07135705376022E-05" ixy="1.3856374474727E-18" ixz="-6.2925381710409E-19" iyy="3.4947428339052E-05" iyz="1.16340041790674E-05" izz="3.34756139191196E-05"/>
    </inertial>
    <visual>
      <origin rpy="0 0 0" xyz="0 0 0"/>
      <geometry>
        <mesh filename="package://minnav_moma_description/meshes/v3/UniwheelPivot_RF.STL"/>
      </geometry>
      <material name="">
        <color rgba="0.752941176470588 0.752941176470588 0.752941176470588 1"/>
      </material>
    </visual>
    <collision>
      <origin rpy="0 0 0" xyz="0 0 0"/>
      <geometry>
        <mesh filename="package://minnav_moma_description/meshes/v3/UniwheelPivot_RF.STL"/>
      </geometry>
    </collision>
  </link>
  <joint name="JT_UniwheelPivot_RF" type="continuous">
    <origin rpy="0 0 1.5708" xyz="0.2 -0.1435 0.031"/>
    <parent link="moma_base_link"/>
    <child link="UniwheelPivot_RF"/>
    <axis xyz="0 0 1"/>
  </joint>
  <link name="Uniwheel_RF">
    <inertial>
      <origin rpy="0 0 0" xyz="3.81426298323717E-08 -2.14332610826151E-08 -1.63217898641044E-08"/>
      <mass value="0.131455385710739"/>
      <inertia ixx="4.67614248550028E-05" ixy="2.92736299627237E-11" ixz="-4.25507933403539E-11" iyy="8.85134139088377E-05" iyz="-1.15416488470831E-11" izz="4.67630636590929E-05"/>
    </inertial>
    <visual>
      <origin rpy="0 0 0" xyz="0 0 0"/>
      <geometry>
        <mesh filename="package://minnav_moma_description/meshes/v3/Uniwheel_RF.STL"/>
      </geometry>
      <material name="">
        <color rgba="0.752941176470588 0.752941176470588 0.752941176470588 1"/>
      </material>
    </visual>
    <collision>
      <origin rpy="0 0 0" xyz="0 0 0"/>
      <geometry>
        <mesh filename="package://minnav_moma_description/meshes/v3/Uniwheel_RF.STL"/>
      </geometry>
    </collision>
  </link>
  <joint name="JT_Uniwheel_RF" type="continuous">
    <origin rpy="0 -0.11262 1.5708" xyz="0 0.024 -0.0775"/>
    <parent link="UniwheelPivot_RF"/>
    <child link="Uniwheel_RF"/>
    <axis xyz="0 1 0"/>
  </joint>
  <link name="UniwheelPivot_LB">
    <inertial>
      <origin rpy="0 0 0" xyz="2.77555756156289E-17 0.0182260960322876 -0.0642291000155078"/>
      <mass value="0.0847351495375797"/>
      <inertia ixx="6.07135705376023E-05" ixy="3.39738839740087E-20" ixz="-1.64218142542497E-20" iyy="3.4947428339052E-05" iyz="1.16340041790674E-05" izz="3.34756139191196E-05"/>
    </inertial>
    <visual>
      <origin rpy="0 0 0" xyz="0 0 0"/>
      <geometry>
        <mesh filename="package://minnav_moma_description/meshes/v3/UniwheelPivot_LB.STL"/>
      </geometry>
      <material name="">
        <color rgba="0.752941176470588 0.752941176470588 0.752941176470588 1"/>
      </material>
    </visual>
    <collision>
      <origin rpy="0 0 0" xyz="0 0 0"/>
      <geometry>
        <mesh filename="package://minnav_moma_description/meshes/v3/UniwheelPivot_LB.STL"/>
      </geometry>
    </collision>
  </link>
  <joint name="JT_UniwheelPivot_LB" type="continuous">
    <origin rpy="0 0 1.5708" xyz="-0.2 0.1435 0.031"/>
    <parent link="moma_base_link"/>
    <child link="UniwheelPivot_LB"/>
    <axis xyz="0 0 1"/>
  </joint>
  <link name="Uniwheel_LB">
    <inertial>
      <origin rpy="0 0 0" xyz="3.81426298601273E-08 -2.14332609993484E-08 -1.63217898502266E-08"/>
      <mass value="0.131455385710739"/>
      <inertia ixx="4.67614248550029E-05" ixy="2.92736298697553E-11" ixz="-4.25507933407774E-11" iyy="8.85134139088378E-05" iyz="-1.15416488421917E-11" izz="4.6763063659093E-05"/>
    </inertial>
    <visual>
      <origin rpy="0 0 0" xyz="0 0 0"/>
      <geometry>
        <mesh filename="package://minnav_moma_description/meshes/v3/Uniwheel_LB.STL"/>
      </geometry>
      <material name="">
        <color rgba="0.752941176470588 0.752941176470588 0.752941176470588 1"/>
      </material>
    </visual>
    <collision>
      <origin rpy="0 0 0" xyz="0 0 0"/>
      <geometry>
        <mesh filename="package://minnav_moma_description/meshes/v3/Uniwheel_LB.STL"/>
      </geometry>
    </collision>
  </link>
  <joint name="JT_Uniwheel_LB" type="continuous">
    <origin rpy="0 -0.11262 1.5708" xyz="0 0.024 -0.0775"/>
    <parent link="UniwheelPivot_LB"/>
    <child link="Uniwheel_LB"/>
    <axis xyz="0 1 0"/>
  </joint>
  <link name="DriWheel_L">
    <inertial>
      <origin rpy="0 0 0" xyz="0.032101869390081 1.4050399616472E-08 -5.67027796697117E-09"/>
      <mass value="0.55025375587753"/>
      <inertia ixx="0.00101587186790134" ixy="-1.42117906446844E-09" ixz="2.42189453861389E-09" iyy="0.000590551548666396" iyz="8.57135076871467E-09" izz="0.000590534709673099"/>
    </inertial>
    <visual>
      <origin rpy="0 0 0" xyz="0 0 0"/>
      <geometry>
        <mesh filename="package://minnav_moma_description/meshes/v3/DriWheel_L.STL"/>
      </geometry>
      <material name="">
        <color rgba="0.752941176470588 0.752941176470588 0.752941176470588 1"/>
      </material>
    </visual>
    <collision>
      <origin rpy="0 0 0" xyz="0 0 0"/>
      <geometry>
        <mesh filename="package://minnav_moma_description/meshes/v3/DriWheel_L.STL"/>
      </geometry>
    </collision>
  </link>
  <joint name="JT_DriWheel_L" type="continuous">
    <origin rpy="1.5708 0 1.5708" xyz="0 0.1711 0"/>
    <parent link="moma_base_link"/>
    <child link="DriWheel_L"/>
    <axis xyz="1 0 0"/>
  </joint>
  <link name="DriWheel_R">
    <inertial>
      <origin rpy="0 0 0" xyz="-0.032101869390081 1.40503995866108E-08 5.67027798698556E-09"/>
      <mass value="0.550253755877532"/>
      <inertia ixx="0.00101587186790135" ixy="1.42117906464977E-09" ixz="2.42189453862527E-09" iyy="0.000590551548666399" iyz="-8.57135076864949E-09" izz="0.000590534709673102"/>
    </inertial>
    <visual>
      <origin rpy="0 0 0" xyz="0 0 0"/>
      <geometry>
        <mesh filename="package://minnav_moma_description/meshes/v3/DriWheel_R.STL"/>
      </geometry>
      <material name="">
        <color rgba="0.752941176470588 0.752941176470588 0.752941176470588 1"/>
      </material>
    </visual>
    <collision>
      <origin rpy="0 0 0" xyz="0 0 0"/>
      <geometry>
        <mesh filename="package://minnav_moma_description/meshes/v3/DriWheel_R.STL"/>
      </geometry>
    </collision>
  </link>
  <joint name="JT_DriWheel_R" type="continuous">
    <origin rpy="1.5708 0 1.5708" xyz="0 -0.1711 0"/>
    <parent link="moma_base_link"/>
    <child link="DriWheel_R"/>
    <axis xyz="1 0 0"/>
  </joint>
  <link name="camera_mount_link"/>
  <joint name="camera_mount_joint" type="fixed">
    <origin rpy="0 0 0" xyz="0.02 0.1 0.03"/>
    <parent link="Head"/>
    <child link="camera_mount_link"/>
  </joint>
  <!-- minnav_moma robot base and body -->
  <minnav_moma_robot/>
  <!-- links      		mesh_no
   base           		0
   shoulder       		1
   arm            		2
   forearm        		3
   wrist          		4
   arm_mico       		5
   arm_half1 (7dof)		6
   arm_half2 (7dof)		7
   wrist_spherical_1  8
   wrist_spherical_2  9

   hand 3 finger  		55
   hand_2finger   		56
   finger_proximal		57
   finger_distal      58
-->
  <!-- links      		mesh_no
   base           		0
   shoulder       		1
   arm            		2
   forearm        		3
   wrist          		4
   arm_mico       		5
   arm_half1 (7dof)		6
   arm_half2 (7dof)		7
   wrist_spherical_1  8
   wrist_spherical_2  9

   hand 3 finger  		55
   hand_2finger   		56
   finger_proximal		57
   finger_distal      58
-->
  <!-- kinova 7dof arm -->
  <link name="arm_mount_link"/>
  <joint name="arm_mount_joint" type="fixed">
    <origin rpy="0 1.5707963 0" xyz="0.0 0.0 0.0"/>
    <parent link="ArmBase"/>
    <child link="arm_mount_link"/>
  </joint>
  <!-- ros_control plugin -->
  <gazebo>
    <plugin filename="libgazebo_ros_control.so" name="gazebo_ros_control">
      <robotNamespace>j2s6s200</robotNamespace>
      <robotSimType>gazebo_ros_control/DefaultRobotHWSim</robotSimType>
      <legacyModeNS>true</legacyModeNS>
    </plugin>
  </gazebo>
  <link name="j2s6s200_link_base">
    <visual>
      <geometry>
        <mesh filename="package://kinova_description/meshes/base.dae"/>
      </geometry>
      <material name="carbon_fiber">
        <color rgba="0.792156862745098 0.819607843137255 0.933333333333333 1"/>
      </material>
    </visual>
    <collision>
      <geometry>
        <mesh filename="package://kinova_description/meshes/base.dae"/>
      </geometry>
    </collision>
    <inertial>
      <mass value="0.46784"/>
      <origin rpy="0 0 0" xyz="0 0 0.1255"/>
      <inertia ixx="0.000951270861568" ixy="0" ixz="0" iyy="0.000951270861568" iyz="0" izz="0.00037427200000000004"/>
    </inertial>
  </link>
  <joint name="j2s6s200_joint_base" type="fixed">
    <parent link="arm_mount_link"/>
    <child link="j2s6s200_link_base"/>
    <axis xyz="0 0 0"/>
    <origin rpy="0 0 0" xyz="0 0 0"/>
    <dynamics damping="0.0" friction="0.0"/>
  </joint>
  <link name="j2s6s200_link_1">
    <visual>
      <geometry>
        <mesh filename="package://kinova_description/meshes/shoulder.dae"/>
      </geometry>
      <material name="carbon_fiber">
        <color rgba="0.792156862745098 0.819607843137255 0.933333333333333 1"/>
      </material>
    </visual>
    <visual>
      <geometry>
        <mesh filename="package://kinova_description/meshes/ring_big.dae"/>
      </geometry>
    </visual>
    <collision>
      <geometry>
        <mesh filename="package://kinova_description/meshes/shoulder.dae"/>
      </geometry>
    </collision>
    <inertial>
      <mass value="0.7477"/>
      <origin xyz="0 -0.002 -0.0605"/>
      <inertia ixx="0.0015203172520400004" ixy="0" ixz="0" iyy="0.0015203172520400004" iyz="0" izz="0.00059816"/>
    </inertial>
  </link>
  <joint name="j2s6s200_joint_1" type="continuous">
    <parent link="j2s6s200_link_base"/>
    <child link="j2s6s200_link_1"/>
    <axis xyz="0 0 1"/>
    <limit effort="40" velocity="0.6283185307179586"/>
    <origin rpy="0 3.141592653589793 0" xyz="0 0 0.15675"/>
    <dynamics damping="0.0" friction="0.0"/>
  </joint>
  <transmission name="j2s6s200_joint_1_trans">
    <type>transmission_interface/SimpleTransmission</type>
    <joint name="j2s6s200_joint_1">
      <hardwareInterface>hardware_interface/EffortJointInterface</hardwareInterface>
    </joint>
    <actuator name="j2s6s200_joint_1_actuator">
      <hardwareInterface>hardware_interface/EffortJointInterface</hardwareInterface>
      <mechanicalReduction>160</mechanicalReduction>
    </actuator>
  </transmission>
  <!--For torque sensing in simulation-->
  <gazebo reference="j2s6s200_joint_1">
    <provideFeedback>true</provideFeedback>
  </gazebo>
  <gazebo>
    <plugin filename="libgazebo_ros_ft_sensor.so" name="ft_sensor">
      <updateRate>30.0</updateRate>
      <topicName>j2s6s200_joint_1_ft_sensor_topic</topicName>
      <jointName>j2s6s200_joint_1</jointName>
    </plugin>
  </gazebo>
  <link name="j2s6s200_link_2">
    <visual>
      <geometry>
        <mesh filename="package://kinova_description/meshes/arm.dae"/>
      </geometry>
      <material name="carbon_fiber">
        <color rgba="0.792156862745098 0.819607843137255 0.933333333333333 1"/>
      </material>
    </visual>
    <visual>
      <geometry>
        <mesh filename="package://kinova_description/meshes/ring_big.dae"/>
      </geometry>
    </visual>
    <collision>
      <geometry>
        <mesh filename="package://kinova_description/meshes/arm.dae"/>
      </geometry>
    </collision>
    <inertial>
      <mass value="0.99"/>
      <origin xyz="0 -0.2065 -0.01"/>
      <inertia ixx="0.010502207990999999" ixy="0" ixz="0" iyy="0.0007920000000000001" iyz="0" izz="0.010502207990999999"/>
    </inertial>
  </link>
  <joint name="j2s6s200_joint_2" type="revolute">
    <parent link="j2s6s200_link_1"/>
    <child link="j2s6s200_link_2"/>
    <axis xyz="0 0 1"/>
    <limit effort="80" lower="0.8203047484373349" upper="5.462880558742252" velocity="0.6283185307179586"/>
    <origin rpy="-1.5707963267948966 0 3.141592653589793" xyz="0 0.0016 -0.11875"/>
    <dynamics damping="0.0" friction="0.0"/>
  </joint>
  <transmission name="j2s6s200_joint_2_trans">
    <type>transmission_interface/SimpleTransmission</type>
    <joint name="j2s6s200_joint_2">
      <hardwareInterface>hardware_interface/EffortJointInterface</hardwareInterface>
    </joint>
    <actuator name="j2s6s200_joint_2_actuator">
      <hardwareInterface>hardware_interface/EffortJointInterface</hardwareInterface>
      <mechanicalReduction>160</mechanicalReduction>
    </actuator>
  </transmission>
  <!--For torque sensing in simulation-->
  <gazebo reference="j2s6s200_joint_2">
    <provideFeedback>true</provideFeedback>
  </gazebo>
  <gazebo>
    <plugin filename="libgazebo_ros_ft_sensor.so" name="ft_sensor">
      <updateRate>30.0</updateRate>
      <topicName>j2s6s200_joint_2_ft_sensor_topic</topicName>
      <jointName>j2s6s200_joint_2</jointName>
    </plugin>
  </gazebo>
  <link name="j2s6s200_link_3">
    <visual>
      <geometry>
        <mesh filename="package://kinova_description/meshes/forearm.dae"/>
      </geometry>
      <material name="carbon_fiber">
        <color rgba="0.792156862745098 0.819607843137255 0.933333333333333 1"/>
      </material>
    </visual>
    <visual>
      <geometry>
        <mesh filename="package://kinova_description/meshes/ring_big.dae"/>
      </geometry>
    </visual>
    <collision>
      <geometry>
        <mesh filename="package://kinova_description/meshes/forearm.dae"/>
      </geometry>
    </collision>
    <inertial>
      <mass value="0.6763"/>
      <origin xyz="0 0.081 -0.0086"/>
      <inertia ixx="0.0014202243190800001" ixy="0" ixz="0" iyy="0.000304335" iyz="0" izz="0.0014202243190800001"/>
    </inertial>
  </link>
  <joint name="j2s6s200_joint_3" type="revolute">
    <parent link="j2s6s200_link_2"/>
    <child link="j2s6s200_link_3"/>
    <axis xyz="0 0 1"/>
    <limit effort="40" lower="0.33161255787892263" upper="5.951572749300664" velocity="0.6283185307179586"/>
    <origin rpy="0 3.141592653589793 0" xyz="0 -0.410 0"/>
    <dynamics damping="0.0" friction="0.0"/>
  </joint>
  <transmission name="j2s6s200_joint_3_trans">
    <type>transmission_interface/SimpleTransmission</type>
    <joint name="j2s6s200_joint_3">
      <hardwareInterface>hardware_interface/EffortJointInterface</hardwareInterface>
    </joint>
    <actuator name="j2s6s200_joint_3_actuator">
      <hardwareInterface>hardware_interface/EffortJointInterface</hardwareInterface>
      <mechanicalReduction>160</mechanicalReduction>
    </actuator>
  </transmission>
  <!--For torque sensing in simulation-->
  <gazebo reference="j2s6s200_joint_3">
    <provideFeedback>true</provideFeedback>
  </gazebo>
  <gazebo>
    <plugin filename="libgazebo_ros_ft_sensor.so" name="ft_sensor">
      <updateRate>30.0</updateRate>
      <topicName>j2s6s200_joint_3_ft_sensor_topic</topicName>
      <jointName>j2s6s200_joint_3</jointName>
    </plugin>
  </gazebo>
  <link name="j2s6s200_link_4">
    <visual>
      <geometry>
        <mesh filename="package://kinova_description/meshes/wrist_spherical_1.dae"/>
      </geometry>
      <material name="carbon_fiber">
        <color rgba="0.792156862745098 0.819607843137255 0.933333333333333 1"/>
      </material>
    </visual>
    <visual>
      <geometry>
        <mesh filename="package://kinova_description/meshes/ring_small.dae"/>
      </geometry>
    </visual>
    <collision>
      <geometry>
        <mesh filename="package://kinova_description/meshes/wrist_spherical_1.dae"/>
      </geometry>
    </collision>
    <inertial>
      <mass value="0.463"/>
      <origin xyz="0 0.0028848942 -0.0541932613"/>
      <inertia ixx="0.0004321316048000001" ixy="0" ixz="0" iyy="0.0004321316048000001" iyz="0" izz="9.260000000000001e-05"/>
    </inertial>
  </link>
  <joint name="j2s6s200_joint_4" type="continuous">
    <parent link="j2s6s200_link_3"/>
    <child link="j2s6s200_link_4"/>
    <axis xyz="0 0 1"/>
    <limit effort="20" velocity="0.8377580409572781"/>
    <origin rpy="-1.5707963267948966 0 3.141592653589793" xyz="0 0.2073 -0.0114"/>
    <dynamics damping="0.0" friction="0.0"/>
  </joint>
  <transmission name="j2s6s200_joint_4_trans">
    <type>transmission_interface/SimpleTransmission</type>
    <joint name="j2s6s200_joint_4">
      <hardwareInterface>hardware_interface/EffortJointInterface</hardwareInterface>
    </joint>
    <actuator name="j2s6s200_joint_4_actuator">
      <hardwareInterface>hardware_interface/EffortJointInterface</hardwareInterface>
      <mechanicalReduction>160</mechanicalReduction>
    </actuator>
  </transmission>
  <!--For torque sensing in simulation-->
  <gazebo reference="j2s6s200_joint_4">
    <provideFeedback>true</provideFeedback>
  </gazebo>
  <gazebo>
    <plugin filename="libgazebo_ros_ft_sensor.so" name="ft_sensor">
      <updateRate>30.0</updateRate>
      <topicName>j2s6s200_joint_4_ft_sensor_topic</topicName>
      <jointName>j2s6s200_joint_4</jointName>
    </plugin>
  </gazebo>
  <link name="j2s6s200_link_5">
    <visual>
      <geometry>
        <mesh filename="package://kinova_description/meshes/wrist_spherical_2.dae"/>
      </geometry>
      <material name="carbon_fiber">
        <color rgba="0.792156862745098 0.819607843137255 0.933333333333333 1"/>
      </material>
    </visual>
    <visual>
      <geometry>
        <mesh filename="package://kinova_description/meshes/ring_small.dae"/>
      </geometry>
    </visual>
    <collision>
      <geometry>
        <mesh filename="package://kinova_description/meshes/wrist_spherical_2.dae"/>
      </geometry>
    </collision>
    <inertial>
      <mass value="0.463"/>
      <origin xyz="0 0.0497208855 -0.0028562765"/>
      <inertia ixx="0.0004321316048000001" ixy="0" ixz="0" iyy="9.260000000000001e-05" iyz="0" izz="0.0004321316048000001"/>
    </inertial>
  </link>
  <joint name="j2s6s200_joint_5" type="revolute">
    <parent link="j2s6s200_link_4"/>
    <child link="j2s6s200_link_5"/>
    <axis xyz="0 0 1"/>
    <limit effort="20" lower="0.5235987755982988" upper="5.759586531581287" velocity="0.8377580409572781"/>
    <origin rpy="1.5707963267948966 0 3.141592653589793" xyz="0 0 -0.10375"/>
    <dynamics damping="0.0" friction="0.0"/>
  </joint>
  <transmission name="j2s6s200_joint_5_trans">
    <type>transmission_interface/SimpleTransmission</type>
    <joint name="j2s6s200_joint_5">
      <hardwareInterface>hardware_interface/EffortJointInterface</hardwareInterface>
    </joint>
    <actuator name="j2s6s200_joint_5_actuator">
      <hardwareInterface>hardware_interface/EffortJointInterface</hardwareInterface>
      <mechanicalReduction>160</mechanicalReduction>
    </actuator>
  </transmission>
  <!--For torque sensing in simulation-->
  <gazebo reference="j2s6s200_joint_5">
    <provideFeedback>true</provideFeedback>
  </gazebo>
  <gazebo>
    <plugin filename="libgazebo_ros_ft_sensor.so" name="ft_sensor">
      <updateRate>30.0</updateRate>
      <topicName>j2s6s200_joint_5_ft_sensor_topic</topicName>
      <jointName>j2s6s200_joint_5</jointName>
    </plugin>
  </gazebo>
  <link name="j2s6s200_link_6">
    <visual>
      <geometry>
        <mesh filename="package://kinova_description/meshes/hand_2finger.dae"/>
      </geometry>
      <material name="carbon_fiber">
        <color rgba="0.792156862745098 0.819607843137255 0.933333333333333 1"/>
      </material>
    </visual>
    <visual>
      <geometry>
        <mesh filename="package://kinova_description/meshes/ring_small.dae"/>
      </geometry>
    </visual>
    <collision>
      <geometry>
        <mesh filename="package://kinova_description/meshes/hand_2finger.dae"/>
      </geometry>
    </collision>
    <inertial>
      <mass value="0.99"/>
      <origin xyz="0 0 -0.06"/>
      <inertia ixx="0.00034532361869999995" ixy="0" ixz="0" iyy="0.00034532361869999995" iyz="0" izz="0.0005815999999999999"/>
    </inertial>
  </link>
  <joint name="j2s6s200_joint_6" type="continuous">
    <parent link="j2s6s200_link_5"/>
    <child link="j2s6s200_link_6"/>
    <axis xyz="0 0 1"/>
    <limit effort="20" velocity="0.8377580409572781"/>
    <origin rpy="-1.5707963267948966 0 3.141592653589793" xyz="0 0.10375 0"/>
    <dynamics damping="0.0" friction="0.0"/>
  </joint>
  <transmission name="j2s6s200_joint_6_trans">
    <type>transmission_interface/SimpleTransmission</type>
    <joint name="j2s6s200_joint_6">
      <hardwareInterface>hardware_interface/EffortJointInterface</hardwareInterface>
    </joint>
    <actuator name="j2s6s200_joint_6_actuator">
      <hardwareInterface>hardware_interface/EffortJointInterface</hardwareInterface>
      <mechanicalReduction>160</mechanicalReduction>
    </actuator>
  </transmission>
  <!--For torque sensing in simulation-->
  <gazebo reference="j2s6s200_joint_6">
    <provideFeedback>true</provideFeedback>
  </gazebo>
  <gazebo>
    <plugin filename="libgazebo_ros_ft_sensor.so" name="ft_sensor">
      <updateRate>30.0</updateRate>
      <topicName>j2s6s200_joint_6_ft_sensor_topic</topicName>
      <jointName>j2s6s200_joint_6</jointName>
    </plugin>
  </gazebo>
  <link name="j2s6s200_end_effector"/>
  <joint name="j2s6s200_joint_end_effector" type="fixed">
    <parent link="j2s6s200_link_6"/>
    <child link="j2s6s200_end_effector"/>
    <axis xyz="0 0 0"/>
    <origin rpy="3.141592653589793 0 1.5707963267948966" xyz="0 0 -0.1600"/>
  </joint>
  <link name="j2s6s200_link_finger_1">
    <visual>
      <geometry>
        <mesh filename="package://kinova_description/meshes/finger_proximal.dae"/>
      </geometry>
      <material name="carbon_fiber">
        <color rgba="0.792156862745098 0.819607843137255 0.933333333333333 1"/>
      </material>
    </visual>
    <collision>
      <geometry>
        <mesh filename="package://kinova_description/meshes/finger_proximal.dae"/>
      </geometry>
    </collision>
    <inertial>
      <mass value="0.01"/>
      <origin xyz="0.022 0 0"/>
      <inertia ixx="7.8999684e-07" ixy="0" ixz="0" iyy="7.8999684e-07" iyz="0" izz="8e-08"/>
    </inertial>
  </link>
  <joint name="j2s6s200_joint_finger_1" type="revolute">
    <parent link="j2s6s200_link_6"/>
    <child link="j2s6s200_link_finger_1"/>
    <axis xyz="0 0 1"/>
    <origin rpy="-1.570796327 .649262481663582 1.57079632679490" xyz="-0.0025 0.03095 -0.11482"/>
    <limit effort="2" lower="0" upper="1.51" velocity="1"/>
  </joint>
  <transmission name="j2s6s200_joint_finger_1_trans">
    <type>transmission_interface/SimpleTransmission</type>
    <joint name="j2s6s200_joint_finger_1">
      <hardwareInterface>hardware_interface/EffortJointInterface</hardwareInterface>
    </joint>
    <actuator name="j2s6s200_joint_finger_1_actuator">
      <hardwareInterface>hardware_interface/EffortJointInterface</hardwareInterface>
      <mechanicalReduction>1</mechanicalReduction>
    </actuator>
  </transmission>
  <link name="j2s6s200_link_finger_tip_1">
    <visual>
      <geometry>
        <mesh filename="package://kinova_description/meshes/finger_distal.dae"/>
      </geometry>
      <material name="carbon_fiber">
        <color rgba="0.792156862745098 0.819607843137255 0.933333333333333 1"/>
      </material>
    </visual>
    <collision>
      <geometry>
        <mesh filename="package://kinova_description/meshes/finger_distal.dae"/>
      </geometry>
    </collision>
    <inertial>
      <mass value="0.01"/>
      <origin xyz="0.022 0 0"/>
      <inertia ixx="7.8999684e-07" ixy="0" ixz="0" iyy="7.8999684e-07" iyz="0" izz="8e-08"/>
    </inertial>
  </link>
  <joint name="j2s6s200_joint_finger_tip_1" type="revolute">
    <parent link="j2s6s200_link_finger_1"/>
    <child link="j2s6s200_link_finger_tip_1"/>
    <axis xyz="0 0 1"/>
    <origin rpy="0 0 0" xyz="0.044 -0.003 0"/>
    <limit effort="2" lower="0" upper="2" velocity="1"/>
  </joint>
  <transmission name="j2s6s200_joint_finger_tip_1_trans">
    <type>transmission_interface/SimpleTransmission</type>
    <joint name="j2s6s200_joint_finger_tip_1">
      <hardwareInterface>hardware_interface/EffortJointInterface</hardwareInterface>
    </joint>
    <actuator name="j2s6s200_joint_finger_tip_1_actuator">
      <hardwareInterface>hardware_interface/EffortJointInterface</hardwareInterface>
      <mechanicalReduction>1</mechanicalReduction>
    </actuator>
  </transmission>
  <link name="j2s6s200_link_finger_2">
    <visual>
      <geometry>
        <mesh filename="package://kinova_description/meshes/finger_proximal.dae"/>
      </geometry>
      <material name="carbon_fiber">
        <color rgba="0.792156862745098 0.819607843137255 0.933333333333333 1"/>
      </material>
    </visual>
    <collision>
      <geometry>
        <mesh filename="package://kinova_description/meshes/finger_proximal.dae"/>
      </geometry>
    </collision>
    <inertial>
      <mass value="0.01"/>
      <origin xyz="0.022 0 0"/>
      <inertia ixx="7.8999684e-07" ixy="0" ixz="0" iyy="7.8999684e-07" iyz="0" izz="8e-08"/>
    </inertial>
  </link>
  <joint name="j2s6s200_joint_finger_2" type="revolute">
    <parent link="j2s6s200_link_6"/>
    <child link="j2s6s200_link_finger_2"/>
    <axis xyz="0 0 1"/>
    <origin rpy="-1.570796327 .649262481663582 -1.57079632679490" xyz="-0.0025 -0.03095 -0.11482"/>
    <limit effort="2" lower="0" upper="1.51" velocity="1"/>
  </joint>
  <transmission name="j2s6s200_joint_finger_2_trans">
    <type>transmission_interface/SimpleTransmission</type>
    <joint name="j2s6s200_joint_finger_2">
      <hardwareInterface>hardware_interface/EffortJointInterface</hardwareInterface>
    </joint>
    <actuator name="j2s6s200_joint_finger_2_actuator">
      <hardwareInterface>hardware_interface/EffortJointInterface</hardwareInterface>
      <mechanicalReduction>1</mechanicalReduction>
    </actuator>
  </transmission>
  <link name="j2s6s200_link_finger_tip_2">
    <visual>
      <geometry>
        <mesh filename="package://kinova_description/meshes/finger_distal.dae"/>
      </geometry>
      <material name="carbon_fiber">
        <color rgba="0.792156862745098 0.819607843137255 0.933333333333333 1"/>
      </material>
    </visual>
    <collision>
      <geometry>
        <mesh filename="package://kinova_description/meshes/finger_distal.dae"/>
      </geometry>
    </collision>
    <inertial>
      <mass value="0.01"/>
      <origin xyz="0.022 0 0"/>
      <inertia ixx="7.8999684e-07" ixy="0" ixz="0" iyy="7.8999684e-07" iyz="0" izz="8e-08"/>
    </inertial>
  </link>
  <joint name="j2s6s200_joint_finger_tip_2" type="revolute">
    <parent link="j2s6s200_link_finger_2"/>
    <child link="j2s6s200_link_finger_tip_2"/>
    <axis xyz="0 0 1"/>
    <origin rpy="0 0 0" xyz="0.044 -0.003 0"/>
    <limit effort="2" lower="0" upper="2" velocity="1"/>
  </joint>
  <transmission name="j2s6s200_joint_finger_tip_2_trans">
    <type>transmission_interface/SimpleTransmission</type>
    <joint name="j2s6s200_joint_finger_tip_2">
      <hardwareInterface>hardware_interface/EffortJointInterface</hardwareInterface>
    </joint>
    <actuator name="j2s6s200_joint_finger_tip_2_actuator">
      <hardwareInterface>hardware_interface/EffortJointInterface</hardwareInterface>
      <mechanicalReduction>1</mechanicalReduction>
    </actuator>
  </transmission>
  <!-- realsense -->
  <link name="realsense_coupling_link">
    <visual>
      <origin rpy="0 0 0" xyz="0 0 0"/>
      <geometry>
        <mesh filename="package://minnav_moma_description/meshes/kinova_realsense_coupling.stl"/>
      </geometry>
      <material name="">
        <color rgba="0.20 0.20 0.20 1"/>
      </material>
    </visual>
  </link>
  <joint name="realsense_coupling_joint" type="fixed">
    <origin rpy="0 0 0" xyz="0 0 0.007"/>
    <parent link="j2s6s200_link_6"/>
    <child link="realsense_coupling_link"/>
  </joint>
  <material name="camera_aluminum">
    <color rgba="0.5 0.5 0.5 1"/>
  </material>
  <!-- camera body, with origin at bottom screw mount -->
  <joint name="camera_joint" type="fixed">
    <origin rpy="0 1.5707965 0" xyz="0.0875 0 -0.01515"/>
    <parent link="realsense_coupling_link"/>
    <child link="camera_bottom_screw_frame"/>
  </joint>
  <link name="camera_bottom_screw_frame"/>
  <joint name="camera_link_joint" type="fixed">
    <origin rpy="0 0 0" xyz="0 0.0175 0.0125"/>
    <parent link="camera_bottom_screw_frame"/>
    <child link="camera_link"/>
  </joint>
  <link name="camera_link">
    <visual>
      <origin rpy="1.5707963267948966 0 1.5707963267948966" xyz="0.0149 -0.0175 0"/>
      <geometry>
        <!-- <box size="${d435_cam_width} ${d435_cam_height} ${d435_cam_depth}"/> -->
        <mesh filename="package://realsense2_description/meshes/d435.dae"/>
        <!--<mesh filename="package://realsense2_description/meshes/d435/d435.dae" />-->
      </geometry>
      <material name="camera_aluminum"/>
    </visual>
    <collision>
      <origin rpy="0 0 0" xyz="0 -0.0175 0"/>
      <geometry>
        <box size="0.02505 0.09 0.025"/>
      </geometry>
    </collision>
    <inertial>
      <!-- The following are not reliable values, and should not be used for modeling -->
      <mass value="0.564"/>
      <origin xyz="0 0 0"/>
      <inertia ixx="0.003881243" ixy="0.0" ixz="0.0" iyy="0.000498940" iyz="0.0" izz="0.003879257"/>
    </inertial>
  </link>
  <!-- camera depth joints and links -->
  <joint name="camera_depth_joint" type="fixed">
    <origin rpy="0 0 0" xyz="0 0 0"/>
    <parent link="camera_link"/>
    <child link="camera_depth_frame"/>
  </joint>
  <link name="camera_depth_frame"/>
  <joint name="camera_depth_optical_joint" type="fixed">
    <origin rpy="-1.5707963267948966 0 -1.5707963267948966" xyz="0 0 0"/>
    <parent link="camera_depth_frame"/>
    <child link="camera_depth_optical_frame"/>
  </joint>
  <link name="camera_depth_optical_frame"/>
  <!-- camera left IR joints and links -->
  <joint name="camera_left_ir_joint" type="fixed">
    <origin rpy="0 0 0" xyz="0 0.0 0"/>
    <parent link="camera_depth_frame"/>
    <child link="camera_left_ir_frame"/>
  </joint>
  <link name="camera_left_ir_frame"/>
  <joint name="camera_left_ir_optical_joint" type="fixed">
    <origin rpy="-1.5707963267948966 0 -1.5707963267948966" xyz="0 0 0"/>
    <parent link="camera_left_ir_frame"/>
    <child link="camera_left_ir_optical_frame"/>
  </joint>
  <link name="camera_left_ir_optical_frame"/>
  <!-- camera right IR joints and links -->
  <joint name="camera_right_ir_joint" type="fixed">
    <origin rpy="0 0 0" xyz="0 -0.05 0"/>
    <parent link="camera_depth_frame"/>
    <child link="camera_right_ir_frame"/>
  </joint>
  <link name="camera_right_ir_frame"/>
  <joint name="camera_right_ir_optical_joint" type="fixed">
    <origin rpy="-1.5707963267948966 0 -1.5707963267948966" xyz="0 0 0"/>
    <parent link="camera_right_ir_frame"/>
    <child link="camera_right_ir_optical_frame"/>
  </joint>
  <link name="camera_right_ir_optical_frame"/>
  <!-- camera color joints and links -->
  <joint name="camera_color_joint" type="fixed">
    <origin rpy="0 0 0" xyz="0 0.015 0"/>
    <parent link="camera_depth_frame"/>
    <child link="camera_color_frame"/>
  </joint>
  <link name="camera_color_frame"/>
  <joint name="camera_color_optical_joint" type="fixed">
    <origin rpy="-1.5707963267948966 0 -1.5707963267948966" xyz="0 0 0"/>
    <parent link="camera_color_frame"/>
    <child link="camera_color_optical_frame"/>
  </joint>
  <link name="camera_color_optical_frame"/>
</robot>

