<?xml version="1.0" encoding="utf-8"?>
<!-- This URDF was automatically created by SolidWorks to URDF Exporter! Originally created by Stephen Brawner (brawner@gmail.com) 
     Commit Version: 1.5.1-0-g916b5db  Build Version: 1.5.7152.31018
     For more information, please see http://wiki.ros.org/sw_urdf_exporter -->
<robot
  name="MOMA_V3_URDF">
  <link
    name="moma_base_link">
    <inertial>
      <origin
        xyz="-0.0697248975605124 9.35986032828009E-05 0.186131310444443"
        rpy="0 0 0" />
      <mass
        value="64.9999523677222" />
      <inertia
        ixx="1.35069488959022"
        ixy="0.000479754719690234"
        ixz="1.48197273533961E-06"
        iyy="0.963094057696194"
        iyz="-7.03349014736132E-06"
        izz="1.34062606564175" />
    </inertial>
    <visual>
      <origin
        xyz="0 0 0"
        rpy="0 0 0" />
      <geometry>
        <mesh
          filename="package://minnav_moma_description/meshes/v3/moma_base_link.STL" />
      </geometry>
      <material
        name="">
        <color
          rgba="0.752941176470588 0.752941176470588 0.752941176470588 1" />
      </material>
    </visual>
    <collision>
      <origin
        xyz="0 0 0"
        rpy="0 0 0" />
      <geometry>
        <mesh
          filename="package://minnav_moma_description/meshes/v3/moma_base_link.STL" />
      </geometry>
    </collision>
  </link>
  <link
    name="ArmBase">
    <inertial>
      <origin
        xyz="-0.0272741114005057 0.00094394189111098 -0.0308551972687778"
        rpy="0 0 0" />
      <mass
        value="0.713162476928904" />
      <inertia
        ixx="0.00220534830451126"
        ixy="8.35547600892114E-07"
        ixz="-6.18305224606399E-05"
        iyy="0.00152386550417795"
        iyz="1.06604349141974E-06"
        izz="0.000996301117911694" />
    </inertial>
    <visual>
      <origin
        xyz="0 0 0"
        rpy="0 0 0" />
      <geometry>
        <mesh
          filename="package://minnav_moma_description/meshes/v3/ArmBase.STL" />
      </geometry>
      <material
        name="">
        <color
          rgba="0.752941176470588 0.752941176470588 0.752941176470588 1" />
      </material>
    </visual>
    <collision>
      <origin
        xyz="0 0 0"
        rpy="0 0 0" />
      <geometry>
        <mesh
          filename="package://minnav_moma_description/meshes/v3/ArmBase.STL" />
      </geometry>
    </collision>
  </link>
  <joint
    name="JT_ArmBase"
    type="prismatic">
    <origin
      xyz="0.034 -0.001 0.3335"
      rpy="0 0 0" />
    <parent
      link="moma_base_link" />
    <child
      link="ArmBase" />
    <axis
      xyz="0 0 1" />
    <limit
      lower="0"
      upper="0.49"
      effort="0"
      velocity="0" />
  </joint>
  <link
    name="LIDAR">
    <inertial>
      <origin
        xyz="8.22216969754708E-05 0.0195154420160331 3.427162408858E-09"
        rpy="0 0 0" />
      <mass
        value="0.102883853456169" />
      <inertia
        ixx="3.66225482144748E-05"
        ixy="1.0587412031796E-07"
        ixz="-3.58548249909878E-12"
        iyy="4.69758377443588E-05"
        iyz="-6.02604694180553E-13"
        izz="3.69805831442243E-05" />
    </inertial>
    <visual>
      <origin
        xyz="0 0 0"
        rpy="0 0 0" />
      <geometry>
        <mesh
          filename="package://minnav_moma_description/meshes/v3/LIDAR.STL" />
      </geometry>
      <material
        name="">
        <color
          rgba="0.752941176470588 0.752941176470588 0.752941176470588 1" />
      </material>
    </visual>
    <collision>
      <origin
        xyz="0 0 0"
        rpy="0 0 0" />
      <geometry>
        <mesh
          filename="package://minnav_moma_description/meshes/v3/LIDAR.STL" />
      </geometry>
    </collision>
  </link>
  <joint
    name="JT_LIDAR"
    type="fixed">
    <origin
      xyz="0.213 0 0.0905"
      rpy="1.5708 0 3.1416" />
    <parent
      link="moma_base_link" />
    <child
      link="LIDAR" />
    <axis
      xyz="0 0 0" />
  </joint>
  <link
    name="Pantilt_PanLink">
    <inertial>
      <origin
        xyz="2.18543483591707E-12 9.36750677027476E-17 0.022419493625198"
        rpy="0 0 0" />
      <mass
        value="0.125638006386443" />
      <inertia
        ixx="5.7984036976015E-05"
        ixy="-4.95095367264507E-09"
        ixz="1.26449088862416E-16"
        iyy="0.000158965664023198"
        iyz="9.95930618769165E-20"
        izz="0.000150893790612493" />
    </inertial>
    <visual>
      <origin
        xyz="0 0 0"
        rpy="0 0 0" />
      <geometry>
        <mesh
          filename="package://minnav_moma_description/meshes/v3/Pantilt_PanLink.STL" />
      </geometry>
      <material
        name="">
        <color
          rgba="0.796078431372549 0.823529411764706 0.937254901960784 1" />
      </material>
    </visual>
    <collision>
      <origin
        xyz="0 0 0"
        rpy="0 0 0" />
      <geometry>
        <mesh
          filename="package://minnav_moma_description/meshes/v3/Pantilt_PanLink.STL" />
      </geometry>
    </collision>
  </link>
  <joint
    name="JT_Pantilt_PanLink"
    type="continuous">
    <origin
      xyz="-0.021 0 1.0081"
      rpy="0 0 -1.5708" />
    <parent
      link="moma_base_link" />
    <child
      link="Pantilt_PanLink" />
    <axis
      xyz="0 0 1" />
  </joint>
  <link
    name="Pantilt_TiltLink">
    <inertial>
      <origin
        xyz="-2.25379299249759E-12 0.031479884333478 1.20049803431499E-13"
        rpy="0 0 0" />
      <mass
        value="0.119003363420873" />
      <inertia
        ixx="7.90464190146043E-05"
        ixy="-3.79029998872968E-16"
        ixz="7.60779981349867E-19"
        iyy="0.00035798448028944"
        iyz="2.37471710121675E-16"
        izz="0.00028284413383159" />
    </inertial>
    <visual>
      <origin
        xyz="0 0 0"
        rpy="0 0 0" />
      <geometry>
        <mesh
          filename="package://minnav_moma_description/meshes/v3/Pantilt_TiltLink.STL" />
      </geometry>
      <material
        name="">
        <color
          rgba="0.796078431372549 0.823529411764706 0.937254901960784 1" />
      </material>
    </visual>
    <collision>
      <origin
        xyz="0 0 0"
        rpy="0 0 0" />
      <geometry>
        <mesh
          filename="package://minnav_moma_description/meshes/v3/Pantilt_TiltLink.STL" />
      </geometry>
    </collision>
  </link>
  <joint
    name="JT_Pantilt_TiltLink"
    type="continuous">
    <origin
      xyz="0 0.00025 0.0413"
      rpy="1.5708 0 3.1416" />
    <parent
      link="Pantilt_PanLink" />
    <child
      link="Pantilt_TiltLink" />
    <axis
      xyz="1 0 0" />
  </joint>
  <link
    name="Head">
    <inertial>
      <origin
        xyz="7.01161821037004E-06 -0.00244242053568144 -0.0752179075942135"
        rpy="0 0 0" />
      <mass
        value="0.398951454797707" />
      <inertia
        ixx="0.000860013559453623"
        ixy="-2.53668430914557E-08"
        ixz="1.00973665605483E-07"
        iyy="0.0018274751159565"
        iyz="5.23242580668497E-06"
        izz="0.0012846248952368" />
    </inertial>
    <visual>
      <origin
        xyz="0 0 0"
        rpy="0 0 0" />
      <geometry>
        <mesh
          filename="package://minnav_moma_description/meshes/v3/Head.STL" />
      </geometry>
      <material
        name="">
        <color
          rgba="0.752941176470588 0.752941176470588 0.752941176470588 1" />
      </material>
    </visual>
    <collision>
      <origin
        xyz="0 0 0"
        rpy="0 0 0" />
      <geometry>
        <mesh
          filename="package://minnav_moma_description/meshes/v3/Head.STL" />
      </geometry>
    </collision>
  </link>
  <joint
    name="JT_Head"
    type="fixed">
    <origin
      xyz="0 0.0705 0.0795"
      rpy="0 0 0" />
    <parent
      link="Pantilt_TiltLink" />
    <child
      link="Head" />
    <axis
      xyz="0 0 0" />
  </joint>
  <link
    name="UniwheelPivot_LF">
    <inertial>
      <origin
        xyz="-9.15933995315754E-16 0.0182260960322876 -0.0642291000155078"
        rpy="0 0 0" />
      <mass
        value="0.0847351495375798" />
      <inertia
        ixx="6.07135705376024E-05"
        ixy="1.38064990757287E-18"
        ixz="-6.23412902781099E-19"
        iyy="3.49474283390521E-05"
        iyz="1.16340041790674E-05"
        izz="3.34756139191197E-05" />
    </inertial>
    <visual>
      <origin
        xyz="0 0 0"
        rpy="0 0 0" />
      <geometry>
        <mesh
          filename="package://minnav_moma_description/meshes/v3/UniwheelPivot_LF.STL" />
      </geometry>
      <material
        name="">
        <color
          rgba="0.752941176470588 0.752941176470588 0.752941176470588 1" />
      </material>
    </visual>
    <collision>
      <origin
        xyz="0 0 0"
        rpy="0 0 0" />
      <geometry>
        <mesh
          filename="package://minnav_moma_description/meshes/v3/UniwheelPivot_LF.STL" />
      </geometry>
    </collision>
  </link>
  <joint
    name="JT_UniwheelPivot_LF"
    type="continuous">
    <origin
      xyz="0.2 0.1435 0.031"
      rpy="0 0 1.5708" />
    <parent
      link="moma_base_link" />
    <child
      link="UniwheelPivot_LF" />
    <axis
      xyz="0 0 1" />
  </joint>
  <link
    name="UniWheel_LF">
    <inertial>
      <origin
        xyz="3.81426298323717E-08 -2.14332611103707E-08 -1.63217898571655E-08"
        rpy="0 0 0" />
      <mass
        value="0.131455385710739" />
      <inertia
        ixx="4.67614248550029E-05"
        ixy="2.92736299371043E-11"
        ixz="-4.25507933450125E-11"
        iyy="8.85134139088376E-05"
        iyz="-1.15416488880503E-11"
        izz="4.6763063659093E-05" />
    </inertial>
    <visual>
      <origin
        xyz="0 0 0"
        rpy="0 0 0" />
      <geometry>
        <mesh
          filename="package://minnav_moma_description/meshes/v3/UniWheel_LF.STL" />
      </geometry>
      <material
        name="">
        <color
          rgba="0.752941176470588 0.752941176470588 0.752941176470588 1" />
      </material>
    </visual>
    <collision>
      <origin
        xyz="0 0 0"
        rpy="0 0 0" />
      <geometry>
        <mesh
          filename="package://minnav_moma_description/meshes/v3/UniWheel_LF.STL" />
      </geometry>
    </collision>
  </link>
  <joint
    name="JT_UniWheel_LF"
    type="continuous">
    <origin
      xyz="0 0.024 -0.0775"
      rpy="0 -0.11262 1.5708" />
    <parent
      link="UniwheelPivot_LF" />
    <child
      link="UniWheel_LF" />
    <axis
      xyz="0 1 0" />
  </joint>
  <link
    name="UniwheelPivot_RB">
    <inertial>
      <origin
        xyz="-9.71445146547012E-16 0.0182260960322876 -0.0642291000155078"
        rpy="0 0 0" />
      <mass
        value="0.0847351495375797" />
      <inertia
        ixx="6.07135705376023E-05"
        ixy="1.38866328531335E-18"
        ixz="-6.29343822979503E-19"
        iyy="3.4947428339052E-05"
        iyz="1.16340041790674E-05"
        izz="3.34756139191196E-05" />
    </inertial>
    <visual>
      <origin
        xyz="0 0 0"
        rpy="0 0 0" />
      <geometry>
        <mesh
          filename="package://minnav_moma_description/meshes/v3/UniwheelPivot_RB.STL" />
      </geometry>
      <material
        name="">
        <color
          rgba="0.752941176470588 0.752941176470588 0.752941176470588 1" />
      </material>
    </visual>
    <collision>
      <origin
        xyz="0 0 0"
        rpy="0 0 0" />
      <geometry>
        <mesh
          filename="package://minnav_moma_description/meshes/v3/UniwheelPivot_RB.STL" />
      </geometry>
    </collision>
  </link>
  <joint
    name="JT_UniwheelPivot_RB"
    type="continuous">
    <origin
      xyz="-0.2 -0.1435 0.031"
      rpy="0 0 1.5708" />
    <parent
      link="moma_base_link" />
    <child
      link="UniwheelPivot_RB" />
    <axis
      xyz="0 0 1" />
  </joint>
  <link
    name="Uniwheel_RB">
    <inertial>
      <origin
        xyz="3.8142629943394E-08 -2.14332609993484E-08 -1.63217898641044E-08"
        rpy="0 0 0" />
      <mass
        value="0.131455385710739" />
      <inertia
        ixx="4.67614248550025E-05"
        ixy="2.92736298794068E-11"
        ixz="-4.25507933484007E-11"
        iyy="8.85134139088377E-05"
        iyz="-1.15416488244326E-11"
        izz="4.67630636590926E-05" />
    </inertial>
    <visual>
      <origin
        xyz="0 0 0"
        rpy="0 0 0" />
      <geometry>
        <mesh
          filename="package://minnav_moma_description/meshes/v3/Uniwheel_RB.STL" />
      </geometry>
      <material
        name="">
        <color
          rgba="0.752941176470588 0.752941176470588 0.752941176470588 1" />
      </material>
    </visual>
    <collision>
      <origin
        xyz="0 0 0"
        rpy="0 0 0" />
      <geometry>
        <mesh
          filename="package://minnav_moma_description/meshes/v3/Uniwheel_RB.STL" />
      </geometry>
    </collision>
  </link>
  <joint
    name="JT_Uniwheel_RB"
    type="continuous">
    <origin
      xyz="0 0.024 -0.0775"
      rpy="0 -0.11262 1.5708" />
    <parent
      link="UniwheelPivot_RB" />
    <child
      link="Uniwheel_RB" />
    <axis
      xyz="0 1 0" />
  </joint>
  <link
    name="UniwheelPivot_RF">
    <inertial>
      <origin
        xyz="-9.15933995315754E-16 0.0182260960322876 -0.0642291000155078"
        rpy="0 0 0" />
      <mass
        value="0.0847351495375797" />
      <inertia
        ixx="6.07135705376022E-05"
        ixy="1.3856374474727E-18"
        ixz="-6.2925381710409E-19"
        iyy="3.4947428339052E-05"
        iyz="1.16340041790674E-05"
        izz="3.34756139191196E-05" />
    </inertial>
    <visual>
      <origin
        xyz="0 0 0"
        rpy="0 0 0" />
      <geometry>
        <mesh
          filename="package://minnav_moma_description/meshes/v3/UniwheelPivot_RF.STL" />
      </geometry>
      <material
        name="">
        <color
          rgba="0.752941176470588 0.752941176470588 0.752941176470588 1" />
      </material>
    </visual>
    <collision>
      <origin
        xyz="0 0 0"
        rpy="0 0 0" />
      <geometry>
        <mesh
          filename="package://minnav_moma_description/meshes/v3/UniwheelPivot_RF.STL" />
      </geometry>
    </collision>
  </link>
  <joint
    name="JT_UniwheelPivot_RF"
    type="continuous">
    <origin
      xyz="0.2 -0.1435 0.031"
      rpy="0 0 1.5708" />
    <parent
      link="moma_base_link" />
    <child
      link="UniwheelPivot_RF" />
    <axis
      xyz="0 0 1" />
  </joint>
  <link
    name="Uniwheel_RF">
    <inertial>
      <origin
        xyz="3.81426298323717E-08 -2.14332610826151E-08 -1.63217898641044E-08"
        rpy="0 0 0" />
      <mass
        value="0.131455385710739" />
      <inertia
        ixx="4.67614248550028E-05"
        ixy="2.92736299627237E-11"
        ixz="-4.25507933403539E-11"
        iyy="8.85134139088377E-05"
        iyz="-1.15416488470831E-11"
        izz="4.67630636590929E-05" />
    </inertial>
    <visual>
      <origin
        xyz="0 0 0"
        rpy="0 0 0" />
      <geometry>
        <mesh
          filename="package://minnav_moma_description/meshes/v3/Uniwheel_RF.STL" />
      </geometry>
      <material
        name="">
        <color
          rgba="0.752941176470588 0.752941176470588 0.752941176470588 1" />
      </material>
    </visual>
    <collision>
      <origin
        xyz="0 0 0"
        rpy="0 0 0" />
      <geometry>
        <mesh
          filename="package://minnav_moma_description/meshes/v3/Uniwheel_RF.STL" />
      </geometry>
    </collision>
  </link>
  <joint
    name="JT_Uniwheel_RF"
    type="continuous">
    <origin
      xyz="0 0.024 -0.0775"
      rpy="0 -0.11262 1.5708" />
    <parent
      link="UniwheelPivot_RF" />
    <child
      link="Uniwheel_RF" />
    <axis
      xyz="0 1 0" />
  </joint>
  <link
    name="UniwheelPivot_LB">
    <inertial>
      <origin
        xyz="2.77555756156289E-17 0.0182260960322876 -0.0642291000155078"
        rpy="0 0 0" />
      <mass
        value="0.0847351495375797" />
      <inertia
        ixx="6.07135705376023E-05"
        ixy="3.39738839740087E-20"
        ixz="-1.64218142542497E-20"
        iyy="3.4947428339052E-05"
        iyz="1.16340041790674E-05"
        izz="3.34756139191196E-05" />
    </inertial>
    <visual>
      <origin
        xyz="0 0 0"
        rpy="0 0 0" />
      <geometry>
        <mesh
          filename="package://minnav_moma_description/meshes/v3/UniwheelPivot_LB.STL" />
      </geometry>
      <material
        name="">
        <color
          rgba="0.752941176470588 0.752941176470588 0.752941176470588 1" />
      </material>
    </visual>
    <collision>
      <origin
        xyz="0 0 0"
        rpy="0 0 0" />
      <geometry>
        <mesh
          filename="package://minnav_moma_description/meshes/v3/UniwheelPivot_LB.STL" />
      </geometry>
    </collision>
  </link>
  <joint
    name="JT_UniwheelPivot_LB"
    type="continuous">
    <origin
      xyz="-0.2 0.1435 0.031"
      rpy="0 0 1.5708" />
    <parent
      link="moma_base_link" />
    <child
      link="UniwheelPivot_LB" />
    <axis
      xyz="0 0 1" />
  </joint>
  <link
    name="Uniwheel_LB">
    <inertial>
      <origin
        xyz="3.81426298601273E-08 -2.14332609993484E-08 -1.63217898502266E-08"
        rpy="0 0 0" />
      <mass
        value="0.131455385710739" />
      <inertia
        ixx="4.67614248550029E-05"
        ixy="2.92736298697553E-11"
        ixz="-4.25507933407774E-11"
        iyy="8.85134139088378E-05"
        iyz="-1.15416488421917E-11"
        izz="4.6763063659093E-05" />
    </inertial>
    <visual>
      <origin
        xyz="0 0 0"
        rpy="0 0 0" />
      <geometry>
        <mesh
          filename="package://minnav_moma_description/meshes/v3/Uniwheel_LB.STL" />
      </geometry>
      <material
        name="">
        <color
          rgba="0.752941176470588 0.752941176470588 0.752941176470588 1" />
      </material>
    </visual>
    <collision>
      <origin
        xyz="0 0 0"
        rpy="0 0 0" />
      <geometry>
        <mesh
          filename="package://minnav_moma_description/meshes/v3/Uniwheel_LB.STL" />
      </geometry>
    </collision>
  </link>
  <joint
    name="JT_Uniwheel_LB"
    type="continuous">
    <origin
      xyz="0 0.024 -0.0775"
      rpy="0 -0.11262 1.5708" />
    <parent
      link="UniwheelPivot_LB" />
    <child
      link="Uniwheel_LB" />
    <axis
      xyz="0 1 0" />
  </joint>
  <link
    name="DriWheel_L">
    <inertial>
      <origin
        xyz="0.032101869390081 1.4050399616472E-08 -5.67027796697117E-09"
        rpy="0 0 0" />
      <mass
        value="0.55025375587753" />
      <inertia
        ixx="0.00101587186790134"
        ixy="-1.42117906446844E-09"
        ixz="2.42189453861389E-09"
        iyy="0.000590551548666396"
        iyz="8.57135076871467E-09"
        izz="0.000590534709673099" />
    </inertial>
    <visual>
      <origin
        xyz="0 0 0"
        rpy="0 0 0" />
      <geometry>
        <mesh
          filename="package://minnav_moma_description/meshes/v3/DriWheel_L.STL" />
      </geometry>
      <material
        name="">
        <color
          rgba="0.752941176470588 0.752941176470588 0.752941176470588 1" />
      </material>
    </visual>
    <collision>
      <origin
        xyz="0 0 0"
        rpy="0 0 0" />
      <geometry>
        <mesh
          filename="package://minnav_moma_description/meshes/v3/DriWheel_L.STL" />
      </geometry>
    </collision>
  </link>
  <joint
    name="JT_DriWheel_L"
    type="continuous">
    <origin
      xyz="0 0.1711 0"
      rpy="1.5708 0 1.5708" />
    <parent
      link="moma_base_link" />
    <child
      link="DriWheel_L" />
    <axis
      xyz="1 0 0" />
  </joint>
  <link
    name="DriWheel_R">
    <inertial>
      <origin
        xyz="-0.032101869390081 1.40503995866108E-08 5.67027798698556E-09"
        rpy="0 0 0" />
      <mass
        value="0.550253755877532" />
      <inertia
        ixx="0.00101587186790135"
        ixy="1.42117906464977E-09"
        ixz="2.42189453862527E-09"
        iyy="0.000590551548666399"
        iyz="-8.57135076864949E-09"
        izz="0.000590534709673102" />
    </inertial>
    <visual>
      <origin
        xyz="0 0 0"
        rpy="0 0 0" />
      <geometry>
        <mesh
          filename="package://minnav_moma_description/meshes/v3/DriWheel_R.STL" />
      </geometry>
      <material
        name="">
        <color
          rgba="0.752941176470588 0.752941176470588 0.752941176470588 1" />
      </material>
    </visual>
    <collision>
      <origin
        xyz="0 0 0"
        rpy="0 0 0" />
      <geometry>
        <mesh
          filename="package://minnav_moma_description/meshes/v3/DriWheel_R.STL" />
      </geometry>
    </collision>
  </link>
  <joint
    name="JT_DriWheel_R"
    type="continuous">
    <origin
      xyz="0 -0.1711 0"
      rpy="1.5708 0 1.5708" />
    <parent
      link="moma_base_link" />
    <child
      link="DriWheel_R" />
    <axis
      xyz="1 0 0" />
  </joint>
</robot>