<?xml version="1.0" encoding="utf-8"?>
<!-- This URDF was automatically created by SolidWorks to URDF Exporter! Originally created by Stephen Brawner (brawner@gmail.com) 
     Commit Version: 1.5.1-0-g916b5db  Build Version: 1.5.7152.31018
     For more information, please see http://wiki.ros.org/sw_urdf_exporter -->
<robot
  name="MOMA_V3_URDF">
  <link
    name="moma_base_link">
    <inertial>
      <origin
        xyz="-0.0697248975605124 9.35986032827709E-05 0.185981353903013"
        rpy="0 0 0" />
      <mass
        value="64.9999523677222" />
      <inertia
        ixx="1.35069488959022"
        ixy="0.000479754719690261"
        ixz="1.48197273532436E-06"
        iyy="0.963094057696193"
        iyz="-7.03349014735604E-06"
        izz="1.34062606564175" />
    </inertial>
    <visual>
      <origin
        xyz="0 0 0"
        rpy="0 0 0" />
      <geometry>
        <mesh
          filename="package://minnav_moma_description/meshes/v3/moma_base_link.STL" />
      </geometry>
      <material
        name="">
        <color
          rgba="0.752941176470588 0.752941176470588 0.752941176470588 1" />
      </material>
    </visual>
    <collision>
      <origin
        xyz="0 0 0"
        rpy="0 0 0" />
      <geometry>
        <mesh
          filename="package://minnav_moma_description/meshes/v3/moma_base_link.STL" />
      </geometry>
    </collision>
  </link>
  <link
    name="ArmBase">
    <inertial>
      <origin
        xyz="0.0308551972687778 0.000943941891110974 -0.0272741114005047"
        rpy="0 0 0" />
      <mass
        value="0.713162476928903" />
      <inertia
        ixx="0.000996301117911692"
        ixy="-1.06604349141997E-06"
        ixz="6.18305224606402E-05"
        iyy="0.00152386550417795"
        iyz="8.35547600892191E-07"
        izz="0.00220534830451125" />
    </inertial>
    <visual>
      <origin
        xyz="0 0 0"
        rpy="0 0 0" />
      <geometry>
        <mesh
          filename="package://minnav_moma_description/meshes/v3/ArmBase.STL" />
      </geometry>
      <material
        name="">
        <color
          rgba="0.752941176470588 0.752941176470588 0.752941176470588 1" />
      </material>
    </visual>
    <collision>
      <origin
        xyz="0 0 0"
        rpy="0 0 0" />
      <geometry>
        <mesh
          filename="package://minnav_moma_description/meshes/v3/ArmBase.STL" />
      </geometry>
    </collision>
  </link>
  <joint
    name="JT_ArmBase"
    type="prismatic">
    <origin
      xyz="0.034 -0.001 0.33335"
      rpy="0 1.5708 0" />
    <parent
      link="moma_base_link" />
    <child
      link="ArmBase" />
    <axis
      xyz="-1 0 0" />
    <limit
      lower="0"
      upper="0.49"
      effort="0"
      velocity="0" />
  </joint>
  <link
    name="LIDAR">
    <inertial>
      <origin
        xyz="8.22216969754985E-05 0.0193654420160331 3.42716239184634E-09"
        rpy="0 0 0" />
      <mass
        value="0.102883853456169" />
      <inertia
        ixx="3.66225482144748E-05"
        ixy="1.05874120317964E-07"
        ixz="-3.58548250047766E-12"
        iyy="4.69758377443588E-05"
        iyz="-6.02604708198514E-13"
        izz="3.69805831442244E-05" />
    </inertial>
    <visual>
      <origin
        xyz="0 0 0"
        rpy="0 0 0" />
      <geometry>
        <mesh
          filename="package://minnav_moma_description/meshes/v3/LIDAR.STL" />
      </geometry>
      <material
        name="">
        <color
          rgba="0.752941176470588 0.752941176470588 0.752941176470588 1" />
      </material>
    </visual>
    <collision>
      <origin
        xyz="0 0 0"
        rpy="0 0 0" />
      <geometry>
        <mesh
          filename="package://minnav_moma_description/meshes/v3/LIDAR.STL" />
      </geometry>
    </collision>
  </link>
  <joint
    name="JT_LIDAR"
    type="fixed">
    <origin
      xyz="0.213 0 0.0905"
      rpy="1.5708 0 3.1416" />
    <parent
      link="moma_base_link" />
    <child
      link="LIDAR" />
    <axis
      xyz="0 0 0" />
  </joint>
  <link
    name="Pantilt_PanLink">
    <inertial>
      <origin
        xyz="9.46734950619818E-13 -6.93889390390723E-18 0.0222694936250953"
        rpy="0 0 0" />
      <mass
        value="0.125638006386443" />
      <inertia
        ixx="5.79840369760151E-05"
        ixy="-4.95095367264464E-09"
        ixz="1.2645288871398E-16"
        iyy="0.000158965664023198"
        iyz="1.00825085563714E-19"
        izz="0.000150893790612493" />
    </inertial>
    <visual>
      <origin
        xyz="0 0 0"
        rpy="0 0 0" />
      <geometry>
        <mesh
          filename="package://minnav_moma_description/meshes/v3/Pantilt_PanLink.STL" />
      </geometry>
      <material
        name="">
        <color
          rgba="0.796078431372549 0.823529411764706 0.937254901960784 1" />
      </material>
    </visual>
    <collision>
      <origin
        xyz="0 0 0"
        rpy="0 0 0" />
      <geometry>
        <mesh
          filename="package://minnav_moma_description/meshes/v3/Pantilt_PanLink.STL" />
      </geometry>
    </collision>
  </link>
  <joint
    name="JT_Pantilt_PanLink"
    type="continuous">
    <origin
      xyz="-0.021 0 1.0081"
      rpy="0 0 -1.5708" />
    <parent
      link="moma_base_link" />
    <child
      link="Pantilt_PanLink" />
    <axis
      xyz="0 0 1" />
  </joint>
  <link
    name="Pantilt_TiltLink">
    <inertial>
      <origin
        xyz="-1.01514245288246E-12 0.0313298843333751 1.19935311682084E-13"
        rpy="0 0 0" />
      <mass
        value="0.119003363420873" />
      <inertia
        ixx="7.90464190146044E-05"
        ixy="-3.7930308239447E-16"
        ixz="7.25178903267415E-19"
        iyy="0.000357984480289441"
        iyz="2.37464872755947E-16"
        izz="0.000282844133831591" />
    </inertial>
    <visual>
      <origin
        xyz="0 0 0"
        rpy="0 0 0" />
      <geometry>
        <mesh
          filename="package://minnav_moma_description/meshes/v3/Pantilt_TiltLink.STL" />
      </geometry>
      <material
        name="">
        <color
          rgba="0.796078431372549 0.823529411764706 0.937254901960784 1" />
      </material>
    </visual>
    <collision>
      <origin
        xyz="0 0 0"
        rpy="0 0 0" />
      <geometry>
        <mesh
          filename="package://minnav_moma_description/meshes/v3/Pantilt_TiltLink.STL" />
      </geometry>
    </collision>
  </link>
  <joint
    name="JT_Pantilt_TiltLink"
    type="continuous">
    <origin
      xyz="0 0.00025 0.0413"
      rpy="1.5708 0 3.1416" />
    <parent
      link="Pantilt_PanLink" />
    <child
      link="Pantilt_TiltLink" />
    <axis
      xyz="1 0 0" />
  </joint>
  <link
    name="Head">
    <inertial>
      <origin
        xyz="7.0065988965367E-06 -0.00259242159541651 -0.0752179059112314"
        rpy="0 0 0" />
      <mass
        value="0.398951265503435" />
      <inertia
        ixx="0.00086001336503175"
        ixy="-2.54365366746701E-08"
        ixz="1.01054446801158E-07"
        iyy="0.00182747472860193"
        iyz="5.23240564256016E-06"
        izz="0.00128462467137371" />
    </inertial>
    <visual>
      <origin
        xyz="0 0 0"
        rpy="0 0 0" />
      <geometry>
        <mesh
          filename="package://minnav_moma_description/meshes/v3/Head.STL" />
      </geometry>
      <material
        name="">
        <color
          rgba="0.752941176470588 0.752941176470588 0.752941176470588 1" />
      </material>
    </visual>
    <collision>
      <origin
        xyz="0 0 0"
        rpy="0 0 0" />
      <geometry>
        <mesh
          filename="package://minnav_moma_description/meshes/v3/Head.STL" />
      </geometry>
    </collision>
  </link>
  <joint
    name="JT_Head"
    type="fixed">
    <origin
      xyz="0 0.0705 0.0795"
      rpy="0 0 0" />
    <parent
      link="Pantilt_TiltLink" />
    <child
      link="Head" />
    <axis
      xyz="0 0 0" />
  </joint>
  <link
    name="UniwheelPivot_LF">
    <inertial>
      <origin
        xyz="-9.15933995315754E-16 0.0182260960322876 -0.0642291000155078"
        rpy="0 0 0" />
      <mass
        value="0.0847351495375796" />
      <inertia
        ixx="6.07135705376022E-05"
        ixy="1.38106507705782E-18"
        ixz="-6.2166420742629E-19"
        iyy="3.49474283390519E-05"
        iyz="1.16340041790674E-05"
        izz="3.34756139191196E-05" />
    </inertial>
    <visual>
      <origin
        xyz="0 0 0"
        rpy="0 0 0" />
      <geometry>
        <mesh
          filename="package://minnav_moma_description/meshes/v3/UniwheelPivot_LF.STL" />
      </geometry>
      <material
        name="">
        <color
          rgba="0.752941176470588 0.752941176470588 0.752941176470588 1" />
      </material>
    </visual>
    <collision>
      <origin
        xyz="0 0 0"
        rpy="0 0 0" />
      <geometry>
        <mesh
          filename="package://minnav_moma_description/meshes/v3/UniwheelPivot_LF.STL" />
      </geometry>
    </collision>
  </link>
  <joint
    name="JT_UniwheelPivot_LF"
    type="continuous">
    <origin
      xyz="0.2 0.1435 0.03085"
      rpy="0 0 1.5708" />
    <parent
      link="moma_base_link" />
    <child
      link="UniwheelPivot_LF" />
    <axis
      xyz="0 0 1" />
  </joint>
  <link
    name="UniWheel_LF">
    <inertial>
      <origin
        xyz="-1.68194530534294E-05 -2.14332612491486E-08 -0.000149066049960667"
        rpy="0 0 0" />
      <mass
        value="0.131455385710739" />
      <inertia
        ixx="4.67614248550021E-05"
        ixy="2.92736299193443E-11"
        ixz="-4.25507933619532E-11"
        iyy="8.85134139088377E-05"
        iyz="-1.15416487550843E-11"
        izz="4.67630636590922E-05" />
    </inertial>
    <visual>
      <origin
        xyz="0 0 0"
        rpy="0 0 0" />
      <geometry>
        <mesh
          filename="package://minnav_moma_description/meshes/v3/UniWheel_LF.STL" />
      </geometry>
      <material
        name="">
        <color
          rgba="0.752941176470588 0.752941176470588 0.752941176470588 1" />
      </material>
    </visual>
    <collision>
      <origin
        xyz="0 0 0"
        rpy="0 0 0" />
      <geometry>
        <mesh
          filename="package://minnav_moma_description/meshes/v3/UniWheel_LF.STL" />
      </geometry>
    </collision>
  </link>
  <joint
    name="JT_UniWheel_LF"
    type="continuous">
    <origin
      xyz="0 0.024 -0.07735"
      rpy="0 -0.11262 1.5708" />
    <parent
      link="UniwheelPivot_LF" />
    <child
      link="UniWheel_LF" />
    <axis
      xyz="0 1 0" />
  </joint>
  <link
    name="UniwheelPivot_RB">
    <inertial>
      <origin
        xyz="-9.71445146547012E-16 0.0182260960322876 -0.0642291000155078"
        rpy="0 0 0" />
      <mass
        value="0.0847351495375797" />
      <inertia
        ixx="6.07135705376022E-05"
        ixy="1.38480813148397E-18"
        ixz="-6.24596709306388E-19"
        iyy="3.4947428339052E-05"
        iyz="1.16340041790674E-05"
        izz="3.34756139191196E-05" />
    </inertial>
    <visual>
      <origin
        xyz="0 0 0"
        rpy="0 0 0" />
      <geometry>
        <mesh
          filename="package://minnav_moma_description/meshes/v3/UniwheelPivot_RB.STL" />
      </geometry>
      <material
        name="">
        <color
          rgba="0.752941176470588 0.752941176470588 0.752941176470588 1" />
      </material>
    </visual>
    <collision>
      <origin
        xyz="0 0 0"
        rpy="0 0 0" />
      <geometry>
        <mesh
          filename="package://minnav_moma_description/meshes/v3/UniwheelPivot_RB.STL" />
      </geometry>
    </collision>
  </link>
  <joint
    name="JT_UniwheelPivot_RB"
    type="continuous">
    <origin
      xyz="-0.2 -0.1435 0.03085"
      rpy="0 0 1.5708" />
    <parent
      link="moma_base_link" />
    <child
      link="UniwheelPivot_RB" />
    <axis
      xyz="0 0 1" />
  </joint>
  <link
    name="Uniwheel_RB">
    <inertial>
      <origin
        xyz="-1.68194530534294E-05 -2.14332611658818E-08 -0.000149066049960678"
        rpy="0 0 0" />
      <mass
        value="0.131455385710739" />
      <inertia
        ixx="4.67614248550014E-05"
        ixy="2.92736298994454E-11"
        ixz="-4.25507933348482E-11"
        iyy="8.85134139088376E-05"
        iyz="-1.15416487597378E-11"
        izz="4.67630636590914E-05" />
    </inertial>
    <visual>
      <origin
        xyz="0 0 0"
        rpy="0 0 0" />
      <geometry>
        <mesh
          filename="package://minnav_moma_description/meshes/v3/Uniwheel_RB.STL" />
      </geometry>
      <material
        name="">
        <color
          rgba="0.752941176470588 0.752941176470588 0.752941176470588 1" />
      </material>
    </visual>
    <collision>
      <origin
        xyz="0 0 0"
        rpy="0 0 0" />
      <geometry>
        <mesh
          filename="package://minnav_moma_description/meshes/v3/Uniwheel_RB.STL" />
      </geometry>
    </collision>
  </link>
  <joint
    name="JT_Uniwheel_RB"
    type="continuous">
    <origin
      xyz="0 0.024 -0.07735"
      rpy="0 -0.11262 1.5708" />
    <parent
      link="UniwheelPivot_RB" />
    <child
      link="Uniwheel_RB" />
    <axis
      xyz="0 1 0" />
  </joint>
  <link
    name="UniwheelPivot_RF">
    <inertial>
      <origin
        xyz="-9.43689570931383E-16 0.0182260960322876 -0.0642291000155078"
        rpy="0 0 0" />
      <mass
        value="0.0847351495375797" />
      <inertia
        ixx="6.07135705376022E-05"
        ixy="1.38743110380241E-18"
        ixz="-6.26758647323962E-19"
        iyy="3.4947428339052E-05"
        iyz="1.16340041790674E-05"
        izz="3.34756139191196E-05" />
    </inertial>
    <visual>
      <origin
        xyz="0 0 0"
        rpy="0 0 0" />
      <geometry>
        <mesh
          filename="package://minnav_moma_description/meshes/v3/UniwheelPivot_RF.STL" />
      </geometry>
      <material
        name="">
        <color
          rgba="0.752941176470588 0.752941176470588 0.752941176470588 1" />
      </material>
    </visual>
    <collision>
      <origin
        xyz="0 0 0"
        rpy="0 0 0" />
      <geometry>
        <mesh
          filename="package://minnav_moma_description/meshes/v3/UniwheelPivot_RF.STL" />
      </geometry>
    </collision>
  </link>
  <joint
    name="JT_UniwheelPivot_RF"
    type="continuous">
    <origin
      xyz="0.2 -0.1435 0.03085"
      rpy="0 0 1.5708" />
    <parent
      link="moma_base_link" />
    <child
      link="UniwheelPivot_RF" />
    <axis
      xyz="0 0 1" />
  </joint>
  <link
    name="Uniwheel_RF">
    <inertial>
      <origin
        xyz="-1.68194530534849E-05 -2.14332612491486E-08 -0.000149066049960633"
        rpy="0 0 0" />
      <mass
        value="0.131455385710739" />
      <inertia
        ixx="4.67614248550019E-05"
        ixy="2.92736298839029E-11"
        ixz="-4.25507933712706E-11"
        iyy="8.85134139088377E-05"
        iyz="-1.15416487509904E-11"
        izz="4.67630636590919E-05" />
    </inertial>
    <visual>
      <origin
        xyz="0 0 0"
        rpy="0 0 0" />
      <geometry>
        <mesh
          filename="package://minnav_moma_description/meshes/v3/Uniwheel_RF.STL" />
      </geometry>
      <material
        name="">
        <color
          rgba="0.752941176470588 0.752941176470588 0.752941176470588 1" />
      </material>
    </visual>
    <collision>
      <origin
        xyz="0 0 0"
        rpy="0 0 0" />
      <geometry>
        <mesh
          filename="package://minnav_moma_description/meshes/v3/Uniwheel_RF.STL" />
      </geometry>
    </collision>
  </link>
  <joint
    name="JT_Uniwheel_RF"
    type="continuous">
    <origin
      xyz="0 0.024 -0.07735"
      rpy="0 -0.112621897187537 1.57079632679495" />
    <parent
      link="UniwheelPivot_RF" />
    <child
      link="Uniwheel_RF" />
    <axis
      xyz="0 1 0" />
  </joint>
  <link
    name="UniwheelPivot_LB">
    <inertial>
      <origin
        xyz="2.77555756156289E-17 0.0182260960322876 -0.0642291000155078"
        rpy="0 0 0" />
      <mass
        value="0.0847351495375796" />
      <inertia
        ixx="6.07135705376022E-05"
        ixy="3.5793788830815E-20"
        ixz="-1.45373064569161E-20"
        iyy="3.4947428339052E-05"
        iyz="1.16340041790674E-05"
        izz="3.34756139191196E-05" />
    </inertial>
    <visual>
      <origin
        xyz="0 0 0"
        rpy="0 0 0" />
      <geometry>
        <mesh
          filename="package://minnav_moma_description/meshes/v3/UniwheelPivot_LB.STL" />
      </geometry>
      <material
        name="">
        <color
          rgba="0.752941176470588 0.752941176470588 0.752941176470588 1" />
      </material>
    </visual>
    <collision>
      <origin
        xyz="0 0 0"
        rpy="0 0 0" />
      <geometry>
        <mesh
          filename="package://minnav_moma_description/meshes/v3/UniwheelPivot_LB.STL" />
      </geometry>
    </collision>
  </link>
  <joint
    name="JT_UniwheelPivot_LB"
    type="continuous">
    <origin
      xyz="-0.2 0.1435 0.03085"
      rpy="0 0 1.5708" />
    <parent
      link="moma_base_link" />
    <child
      link="UniwheelPivot_LB" />
    <axis
      xyz="0 0 1" />
  </joint>
  <link
    name="Uniwheel_LB">
    <inertial>
      <origin
        xyz="-1.68194530534849E-05 -2.1433261221393E-08 -0.000149066049960664"
        rpy="0 0 0" />
      <mass
        value="0.131455385710739" />
      <inertia
        ixx="4.67614248550014E-05"
        ixy="2.92736298993967E-11"
        ixz="-4.25507933356952E-11"
        iyy="8.85134139088376E-05"
        iyz="-1.15416487599895E-11"
        izz="4.67630636590915E-05" />
    </inertial>
    <visual>
      <origin
        xyz="0 0 0"
        rpy="0 0 0" />
      <geometry>
        <mesh
          filename="package://minnav_moma_description/meshes/v3/Uniwheel_LB.STL" />
      </geometry>
      <material
        name="">
        <color
          rgba="0.752941176470588 0.752941176470588 0.752941176470588 1" />
      </material>
    </visual>
    <collision>
      <origin
        xyz="0 0 0"
        rpy="0 0 0" />
      <geometry>
        <mesh
          filename="package://minnav_moma_description/meshes/v3/Uniwheel_LB.STL" />
      </geometry>
    </collision>
  </link>
  <joint
    name="JT_Uniwheel_LB"
    type="continuous">
    <origin
      xyz="0 0.024 -0.07735"
      rpy="0 -0.112621897187537 1.5707963267949" />
    <parent
      link="UniwheelPivot_LB" />
    <child
      link="Uniwheel_LB" />
    <axis
      xyz="0 1 0" />
  </joint>
  <link
    name="DriWheel_L">
    <inertial>
      <origin
        xyz="0.0316538399728968 1.25157353600119E-08 -5.05093808177879E-09"
        rpy="0 0 0" />
      <mass
        value="0.617725202733258" />
      <inertia
        ixx="0.0013728961373634"
        ixy="-1.42117906446992E-09"
        ixz="2.42189453861375E-09"
        iyy="0.000769266097737994"
        iyz="8.57135076868556E-09"
        izz="0.000769249258744697" />
    </inertial>
    <visual>
      <origin
        xyz="0 0 0"
        rpy="0 0 0" />
      <geometry>
        <mesh
          filename="package://minnav_moma_description/meshes/v3/DriWheel_L.STL" />
      </geometry>
      <material
        name="">
        <color
          rgba="0.752941176470588 0.752941176470588 0.752941176470588 1" />
      </material>
    </visual>
    <collision>
      <origin
        xyz="0 0 0"
        rpy="0 0 0" />
      <geometry>
        <mesh
          filename="package://minnav_moma_description/meshes/v3/DriWheel_L.STL" />
      </geometry>
    </collision>
  </link>
  <joint
    name="JT_DriWheel_L"
    type="continuous">
    <origin
      xyz="0 0.1711 0"
      rpy="1.5708 0 1.5708" />
    <parent
      link="moma_base_link" />
    <child
      link="DriWheel_L" />
    <axis
      xyz="1 0 0" />
  </joint>
  <link
    name="DriWheel_R">
    <inertial>
      <origin
        xyz="-0.0316538399728968 1.25157353677965E-08 5.05093810271229E-09"
        rpy="0 0 0" />
      <mass
        value="0.61772520273326" />
      <inertia
        ixx="0.00137289613736341"
        ixy="1.42117906477149E-09"
        ixz="2.42189453862747E-09"
        iyy="0.000769266097737998"
        iyz="-8.57135076860845E-09"
        izz="0.000769249258744701" />
    </inertial>
    <visual>
      <origin
        xyz="0 0 0"
        rpy="0 0 0" />
      <geometry>
        <mesh
          filename="package://minnav_moma_description/meshes/v3/DriWheel_R.STL" />
      </geometry>
      <material
        name="">
        <color
          rgba="0.752941176470588 0.752941176470588 0.752941176470588 1" />
      </material>
    </visual>
    <collision>
      <origin
        xyz="0 0 0"
        rpy="0 0 0" />
      <geometry>
        <mesh
          filename="package://minnav_moma_description/meshes/v3/DriWheel_R.STL" />
      </geometry>
    </collision>
  </link>
  <joint
    name="JT_DriWheel_R"
    type="continuous">
    <origin
      xyz="0 -0.171100000000101 0"
      rpy="1.5707963267949 0 1.5707963267949" />
    <parent
      link="moma_base_link" />
    <child
      link="DriWheel_R" />
    <axis
      xyz="1 0 0" />
  </joint>
</robot>