<?xml version="1.0" encoding="utf-8"?>
<!-- This URDF was automatically created by SolidWorks to URDF Exporter! Originally created by Stephen Brawner (brawner@gmail.com) 
     Commit Version: 1.5.1-0-g916b5db  Build Version: 1.5.7152.31018
     For more information, please see http://wiki.ros.org/sw_urdf_exporter -->
<robot
  name="WholeUrdfV7_1">
  <link
    name="Base_link">
    <inertial>
      <origin
        xyz="-0.044436 -0.0062652 0.2648"
        rpy="0 0 0" />
      <mass
        value="58.651" />
      <inertia
        ixx="0.94847"
        ixy="0.095512"
        ixz="0.0011811"
        iyy="0.93891"
        iyz="3.2417E-06"
        izz="1.4338" />
    </inertial>
    <visual>
      <origin
        xyz="0 0 0"
        rpy="0 0 0" />
      <geometry>
        <mesh
          filename="package://WholeUrdfV7_1/meshes/Base_link.STL" />
      </geometry>
      <material
        name="">
        <color
          rgba="0.75294 0.75294 0.75294 1" />
      </material>
    </visual>
    <collision>
      <origin
        xyz="0 0 0"
        rpy="0 0 0" />
      <geometry>
        <mesh
          filename="package://WholeUrdfV7_1/meshes/Base_link.STL" />
      </geometry>
    </collision>
  </link>
  <link
    name="Radar_2D">
    <inertial>
      <origin
        xyz="3.81358176767543E-05 0.0168839488939113 5.55414040220947E-09"
        rpy="0 0 0" />
      <mass
        value="0.196744590422997" />
      <inertia
        ixx="8.3896262005527E-05"
        ixy="1.07929084151387E-07"
        ixz="-3.29780769807581E-11"
        iyy="0.000128231684683343"
        iyz="-1.07899976052585E-11"
        izz="8.42188760618159E-05" />
    </inertial>
    <visual>
      <origin
        xyz="0 0 0"
        rpy="0 0 0" />
      <geometry>
        <mesh
          filename="package://WholeUrdfV7_1/meshes/Radar_2D.STL" />
      </geometry>
      <material
        name="">
        <color
          rgba="0.498039215686275 0.498039215686275 0.498039215686275 1" />
      </material>
    </visual>
    <collision>
      <origin
        xyz="0 0 0"
        rpy="0 0 0" />
      <geometry>
        <mesh
          filename="package://WholeUrdfV7_1/meshes/Radar_2D.STL" />
      </geometry>
    </collision>
  </link>
  <joint
    name="JT_Radar_2D"
    type="fixed">
    <origin
      xyz="0.212 0 0.1475"
      rpy="1.5708 0 -3.1416" />
    <parent
      link="Base_link" />
    <child
      link="Radar_2D" />
    <axis
      xyz="0 0 0" />
  </joint>
  <link
    name="ArmBase">
    <inertial>
      <origin
        xyz="-0.0213735915688368 -0.000303857997027306 -0.023239809881092"
        rpy="0 0 0" />
      <mass
        value="1.92525017908569" />
      <inertia
        ixx="0.0042883271151622"
        ixy="2.36727747261914E-06"
        ixz="-0.000111008140398769"
        iyy="0.00317248222624626"
        iyz="3.33448756395564E-06"
        izz="0.00186223637582919" />
    </inertial>
    <visual>
      <origin
        xyz="0 0 0"
        rpy="0 0 0" />
      <geometry>
        <mesh
          filename="package://WholeUrdfV7_1/meshes/ArmBase.STL" />
      </geometry>
      <material
        name="">
        <color
          rgba="0.752941176470588 0.752941176470588 0.752941176470588 1" />
      </material>
    </visual>
    <collision>
      <origin
        xyz="0 0 0"
        rpy="0 0 0" />
      <geometry>
        <mesh
          filename="package://WholeUrdfV7_1/meshes/ArmBase.STL" />
      </geometry>
    </collision>
  </link>
  <joint
    name="JT_ArmBase"
    type="prismatic">
    <origin
      xyz="0.031926 0.0756 0.3625"
      rpy="0 0 1.5708" />
    <parent
      link="Base_link" />
    <child
      link="ArmBase" />
    <axis
      xyz="0 0 1" />
    <limit
      lower="0"
      upper="0.3"
      effort="0"
      velocity="0" />
  </joint>
  <link
    name="UniWheelBase_LB">
    <inertial>
      <origin
        xyz="0.0182260960322877 2.77555756156289E-17 -0.0287708999844922"
        rpy="0 0 0" />
      <mass
        value="0.0847351495375796" />
      <inertia
        ixx="3.49474283390519E-05"
        ixy="3.57316634759339E-20"
        ixz="-1.16340041790673E-05"
        iyy="6.07135705376021E-05"
        iyz="1.55453116498476E-20"
        izz="3.34756139191196E-05" />
    </inertial>
    <visual>
      <origin
        xyz="0 0 0"
        rpy="0 0 0" />
      <geometry>
        <mesh
          filename="package://WholeUrdfV7_1/meshes/UniWheelBase_LB.STL" />
      </geometry>
      <material
        name="">
        <color
          rgba="0.752941176470588 0.752941176470588 0.752941176470588 1" />
      </material>
    </visual>
    <collision>
      <origin
        xyz="0 0 0"
        rpy="0 0 0" />
      <geometry>
        <mesh
          filename="package://WholeUrdfV7_1/meshes/UniWheelBase_LB.STL" />
      </geometry>
    </collision>
  </link>
  <joint
    name="JT_UniWheelBase_LB"
    type="continuous">
    <origin
      xyz="-0.200000000000008 0.14349999999999 0"
      rpy="3.14159265358979 0 -3.14159265358974" />
    <parent
      link="Base_link" />
    <child
      link="UniWheelBase_LB" />
    <axis
      xyz="0 0 1" />
  </joint>
  <link
    name="UniWheel_LB">
    <inertial>
      <origin
        xyz="3.81426299069648E-08 -2.14332611381263E-08 -1.63217898641044E-08"
        rpy="0 0 0" />
      <mass
        value="0.182722986137927" />
      <inertia
        ixx="6.49983805484529E-05"
        ixy="4.06903456327858E-11"
        ixz="-5.914560273148E-11"
        iyy="0.000123033645333284"
        iyz="-1.60428918574936E-11"
        izz="6.5000658486138E-05" />
    </inertial>
    <visual>
      <origin
        xyz="0 0 0"
        rpy="0 0 0" />
      <geometry>
        <mesh
          filename="package://WholeUrdfV7_1/meshes/UniWheel_LB.STL" />
      </geometry>
      <material
        name="">
        <color
          rgba="0.752941176470588 0.752941176470588 0.752941176470588 1" />
      </material>
    </visual>
    <collision>
      <origin
        xyz="0 0 0"
        rpy="0 0 0" />
      <geometry>
        <mesh
          filename="package://WholeUrdfV7_1/meshes/UniWheel_LB.STL" />
      </geometry>
    </collision>
  </link>
  <joint
    name="JT_UniWheel_LB"
    type="continuous">
    <origin
      xyz="0.024 0 -0.0155"
      rpy="3.14159265358979 1.5707963267949 0" />
    <parent
      link="UniWheelBase_LB" />
    <child
      link="UniWheel_LB" />
    <axis
      xyz="0 1 0" />
  </joint>
  <link
    name="UniWheelBase_RB">
    <inertial>
      <origin
        xyz="0.0182260960322876 2.77555756156289E-17 -0.0287708999844922"
        rpy="0 0 0" />
      <mass
        value="0.0847351495375796" />
      <inertia
        ixx="3.49474283390519E-05"
        ixy="3.12437677540417E-20"
        ixz="-1.16340041790674E-05"
        iyy="6.07135705376021E-05"
        iyz="5.18171751242525E-21"
        izz="3.34756139191196E-05" />
    </inertial>
    <visual>
      <origin
        xyz="0 0 0"
        rpy="0 0 0" />
      <geometry>
        <mesh
          filename="package://WholeUrdfV7_1/meshes/UniWheelBase_RB.STL" />
      </geometry>
      <material
        name="">
        <color
          rgba="0.752941176470588 0.752941176470588 0.752941176470588 1" />
      </material>
    </visual>
    <collision>
      <origin
        xyz="0 0 0"
        rpy="0 0 0" />
      <geometry>
        <mesh
          filename="package://WholeUrdfV7_1/meshes/UniWheelBase_RB.STL" />
      </geometry>
    </collision>
  </link>
  <joint
    name="JT_UniWheelBase_RB"
    type="continuous">
    <origin
      xyz="-0.199999999999992 -0.14350000000001 0"
      rpy="-3.14159265358979 0 -3.14159265358974" />
    <parent
      link="Base_link" />
    <child
      link="UniWheelBase_RB" />
    <axis
      xyz="0 0 1" />
  </joint>
  <link
    name="UniWheel_RB">
    <inertial>
      <origin
        xyz="3.81426299086995E-08 -2.14332611658818E-08 -1.632178989186E-08"
        rpy="0 0 0" />
      <mass
        value="0.182722986137927" />
      <inertia
        ixx="6.49983805484528E-05"
        ixy="4.0690345180762E-11"
        ixz="-5.91456027302949E-11"
        iyy="0.000123033645333284"
        iyz="-1.60428918134392E-11"
        izz="6.5000658486138E-05" />
    </inertial>
    <visual>
      <origin
        xyz="0 0 0"
        rpy="0 0 0" />
      <geometry>
        <mesh
          filename="package://WholeUrdfV7_1/meshes/UniWheel_RB.STL" />
      </geometry>
      <material
        name="">
        <color
          rgba="0.752941176470588 0.752941176470588 0.752941176470588 1" />
      </material>
    </visual>
    <collision>
      <origin
        xyz="0 0 0"
        rpy="0 0 0" />
      <geometry>
        <mesh
          filename="package://WholeUrdfV7_1/meshes/UniWheel_RB.STL" />
      </geometry>
    </collision>
  </link>
  <joint
    name="JT_UniWheel_RB"
    type="continuous">
    <origin
      xyz="0.024 0 -0.0155"
      rpy="0 1.5707963267949 0" />
    <parent
      link="UniWheelBase_RB" />
    <child
      link="UniWheel_RB" />
    <axis
      xyz="0 1 0" />
  </joint>
  <link
    name="UniWheelBase_RF">
    <inertial>
      <origin
        xyz="0.0182260960322877 0 -0.0287708999844922"
        rpy="0 0 0" />
      <mass
        value="0.0847351495375795" />
      <inertia
        ixx="3.49474283390519E-05"
        ixy="3.4880166385261E-20"
        ixz="-1.16340041790674E-05"
        iyy="6.07135705376022E-05"
        iyz="1.7847571585088E-20"
        izz="3.34756139191196E-05" />
    </inertial>
    <visual>
      <origin
        xyz="0 0 0"
        rpy="0 0 0" />
      <geometry>
        <mesh
          filename="package://WholeUrdfV7_1/meshes/UniWheelBase_RF.STL" />
      </geometry>
      <material
        name="">
        <color
          rgba="0.752941176470588 0.752941176470588 0.752941176470588 1" />
      </material>
    </visual>
    <collision>
      <origin
        xyz="0 0 0"
        rpy="0 0 0" />
      <geometry>
        <mesh
          filename="package://WholeUrdfV7_1/meshes/UniWheelBase_RF.STL" />
      </geometry>
    </collision>
  </link>
  <joint
    name="JT_UniWheelBase_RF"
    type="continuous">
    <origin
      xyz="0.200000000000008 -0.14349999999999 0"
      rpy="3.14159265358979 0 -3.14159265358974" />
    <parent
      link="Base_link" />
    <child
      link="UniWheelBase_RF" />
    <axis
      xyz="0 0 1" />
  </joint>
  <link
    name="UniWheel_RF">
    <inertial>
      <origin
        xyz="3.81426299034954E-08 -2.14332611658818E-08 -1.632178989186E-08"
        rpy="0 0 0" />
      <mass
        value="0.182722986137927" />
      <inertia
        ixx="6.49983805484531E-05"
        ixy="4.06903453117738E-11"
        ixz="-5.91456027575944E-11"
        iyy="0.000123033645333284"
        iyz="-1.6042891784853E-11"
        izz="6.50006584861382E-05" />
    </inertial>
    <visual>
      <origin
        xyz="0 0 0"
        rpy="0 0 0" />
      <geometry>
        <mesh
          filename="package://WholeUrdfV7_1/meshes/UniWheel_RF.STL" />
      </geometry>
      <material
        name="">
        <color
          rgba="0.752941176470588 0.752941176470588 0.752941176470588 1" />
      </material>
    </visual>
    <collision>
      <origin
        xyz="0 0 0"
        rpy="0 0 0" />
      <geometry>
        <mesh
          filename="package://WholeUrdfV7_1/meshes/UniWheel_RF.STL" />
      </geometry>
    </collision>
  </link>
  <joint
    name="JT_UniWheel_RF"
    type="continuous">
    <origin
      xyz="0.024 0 -0.0155"
      rpy="3.14159265358979 1.5707963267949 0" />
    <parent
      link="UniWheelBase_RF" />
    <child
      link="UniWheel_RF" />
    <axis
      xyz="0 1 0" />
  </joint>
  <link
    name="UniWheelBase_LF">
    <inertial>
      <origin
        xyz="0.0182260960322876 2.77555756156289E-17 -0.0287708999844923"
        rpy="0 0 0" />
      <mass
        value="0.0847351495375795" />
      <inertia
        ixx="3.49474283390519E-05"
        ixy="3.73180431348779E-20"
        ixz="-1.16340041790673E-05"
        iyy="6.07135705376021E-05"
        iyz="1.77432943949963E-20"
        izz="3.34756139191196E-05" />
    </inertial>
    <visual>
      <origin
        xyz="0 0 0"
        rpy="0 0 0" />
      <geometry>
        <mesh
          filename="package://WholeUrdfV7_1/meshes/UniWheelBase_LF.STL" />
      </geometry>
      <material
        name="">
        <color
          rgba="0.752941176470588 0.752941176470588 0.752941176470588 1" />
      </material>
    </visual>
    <collision>
      <origin
        xyz="0 0 0"
        rpy="0 0 0" />
      <geometry>
        <mesh
          filename="package://WholeUrdfV7_1/meshes/UniWheelBase_LF.STL" />
      </geometry>
    </collision>
  </link>
  <joint
    name="JT_UniWheelBase_LF"
    type="continuous">
    <origin
      xyz="0.199999999999993 0.14350000000001 0"
      rpy="3.14159265358979 0 -3.14159265358974" />
    <parent
      link="Base_link" />
    <child
      link="UniWheelBase_LF" />
    <axis
      xyz="0 0 1" />
  </joint>
  <link
    name="UniWheel_LF">
    <inertial>
      <origin
        xyz="3.81426298913523E-08 -2.14332611936374E-08 -1.63217899196155E-08"
        rpy="0 0 0" />
      <mass
        value="0.182722986137927" />
      <inertia
        ixx="6.49983805484538E-05"
        ixy="4.0690345293948E-11"
        ixz="-5.9145602742195E-11"
        iyy="0.000123033645333284"
        iyz="-1.60428918440839E-11"
        izz="6.5000658486139E-05" />
    </inertial>
    <visual>
      <origin
        xyz="0 0 0"
        rpy="0 0 0" />
      <geometry>
        <mesh
          filename="package://WholeUrdfV7_1/meshes/UniWheel_LF.STL" />
      </geometry>
      <material
        name="">
        <color
          rgba="0.752941176470588 0.752941176470588 0.752941176470588 1" />
      </material>
    </visual>
    <collision>
      <origin
        xyz="0 0 0"
        rpy="0 0 0" />
      <geometry>
        <mesh
          filename="package://WholeUrdfV7_1/meshes/UniWheel_LF.STL" />
      </geometry>
    </collision>
  </link>
  <joint
    name="JT_UniWheel_LF"
    type="continuous">
    <origin
      xyz="0.024 0 -0.0155"
      rpy="0 1.5708 0" />
    <parent
      link="UniWheelBase_LF" />
    <child
      link="UniWheel_LF" />
    <axis
      xyz="0 1 0" />
  </joint>
  <link
    name="Radar_3D">
    <inertial>
      <origin
        xyz="-0.0332405985861663 0.050106525400968 0.0344980769248998"
        rpy="0 0 0" />
      <mass
        value="0.545701622476093" />
      <inertia
        ixx="0.000474175468942812"
        ixy="-8.13024320400887E-06"
        ixz="-2.4739021752185E-06"
        iyy="0.000470938119822533"
        iyz="-1.92648566828374E-05"
        izz="0.000248534793624654" />
    </inertial>
    <visual>
      <origin
        xyz="0 0 0"
        rpy="0 0 0" />
      <geometry>
        <mesh
          filename="package://WholeUrdfV7_1/meshes/Radar_3D.STL" />
      </geometry>
      <material
        name="">
        <color
          rgba="0.752941176470588 0.752941176470588 0.752941176470588 1" />
      </material>
    </visual>
    <collision>
      <origin
        xyz="0 0 0"
        rpy="0 0 0" />
      <geometry>
        <mesh
          filename="package://WholeUrdfV7_1/meshes/Radar_3D.STL" />
      </geometry>
    </collision>
  </link>
  <joint
    name="JT_Radar_3D"
    type="fixed">
    <origin
      xyz="-0.071645 -0.072795 1.121"
      rpy="1.5708 0 1.5708" />
    <parent
      link="Base_link" />
    <child
      link="Radar_3D" />
    <axis
      xyz="1 0 0" />
    <limit
      lower="0"
      upper="1.5708"
      effort="0"
      velocity="0" />
  </joint>
  <link
    name="PanTiltLink1">
    <inertial>
      <origin
        xyz="-2.77555756156289E-17 4.85722573273506E-17 0.0224194936251978"
        rpy="0 0 0" />
      <mass
        value="0.125638006386442" />
      <inertia
        ixx="5.79840369760145E-05"
        ixy="-4.95095367251032E-09"
        ixz="-2.06554334975402E-20"
        iyy="0.000158965664023197"
        iyz="-9.64796384693134E-20"
        izz="0.000150893790612493" />
    </inertial>
    <visual>
      <origin
        xyz="0 0 0"
        rpy="0 0 0" />
      <geometry>
        <mesh
          filename="package://WholeUrdfV7_1/meshes/PanTiltLink1.STL" />
      </geometry>
      <material
        name="">
        <color
          rgba="0.796078431372549 0.823529411764706 0.937254901960784 1" />
      </material>
    </visual>
    <collision>
      <origin
        xyz="0 0 0"
        rpy="0 0 0" />
      <geometry>
        <mesh
          filename="package://WholeUrdfV7_1/meshes/PanTiltLink1.STL" />
      </geometry>
    </collision>
  </link>
  <joint
    name="JT_PanTiltLink1"
    type="continuous">
    <origin
      xyz="0.033001 0.10829 1.066"
      rpy="0 0 1.5708" />
    <parent
      link="Base_link" />
    <child
      link="PanTiltLink1" />
    <axis
      xyz="0 0 1" />
  </joint>
  <link
    name="Head">
    <inertial>
      <origin
        xyz="3.010974464486E-05 0.0710465587049527 -0.000410628804097812"
        rpy="0 0 0" />
      <mass
        value="1.09222259990928" />
      <inertia
        ixx="0.00171098700756019"
        ixy="1.83620169698393E-09"
        ixz="1.47977806998734E-07"
        iyy="0.00490559716768774"
        iyz="1.09057098306672E-06"
        izz="0.00518583633786296" />
    </inertial>
    <visual>
      <origin
        xyz="0 0 0"
        rpy="0 0 0" />
      <geometry>
        <mesh
          filename="package://WholeUrdfV7_1/meshes/Head.STL" />
      </geometry>
      <material
        name="">
        <color
          rgba="0.752941176470588 0.752941176470588 0.752941176470588 1" />
      </material>
    </visual>
    <collision>
      <origin
        xyz="0 0 0"
        rpy="0 0 0" />
      <geometry>
        <mesh
          filename="package://WholeUrdfV7_1/meshes/Head.STL" />
      </geometry>
    </collision>
  </link>
  <joint
    name="JT_Head"
    type="continuous">
    <origin
      xyz="0 0.00025 0.0413"
      rpy="1.5708 0 3.1416" />
    <parent
      link="PanTiltLink1" />
    <child
      link="Head" />
    <axis
      xyz="1 0 0" />
  </joint>
  <link
    name="DriWheel_R">
    <inertial>
      <origin
        xyz="-1.3898E-08 -0.032105 6.1246E-09"
        rpy="0 0 0" />
      <mass
        value="0.54895" />
      <inertia
        ixx="0.00059053"
        ixy="-1.3442E-09"
        ixz="8.0241E-09"
        iyy="0.0010159"
        iyz="2.4655E-09"
        izz="0.00059052" />
    </inertial>
    <visual>
      <origin
        xyz="0 0 0"
        rpy="0 0 0" />
      <geometry>
        <mesh
          filename="package://WholeUrdfV7_1/meshes/DriWheel_R.STL" />
      </geometry>
      <material
        name="">
        <color
          rgba="0.75294 0.75294 0.75294 1" />
      </material>
    </visual>
    <collision>
      <origin
        xyz="0 0 0"
        rpy="0 0 0" />
      <geometry>
        <mesh
          filename="package://WholeUrdfV7_1/meshes/DriWheel_R.STL" />
      </geometry>
    </collision>
  </link>
  <joint
    name="JT_DriWheel_R"
    type="continuous">
    <origin
      xyz="0 -0.1719 0.056"
      rpy="0 0 0" />
    <parent
      link="Base_link" />
    <child
      link="DriWheel_R" />
    <axis
      xyz="0 1 0" />
  </joint>
  <link
    name="DriWheel_L">
    <inertial>
      <origin
        xyz="-1.2972E-08 0.032105 -7.5981E-09"
        rpy="0 0 0" />
      <mass
        value="0.54895" />
      <inertia
        ixx="0.00059054"
        ixy="5.3364E-10"
        ixz="-1.3793E-09"
        iyy="0.0010159"
        iyz="2.752E-09"
        izz="0.00059051" />
    </inertial>
    <visual>
      <origin
        xyz="0 0 0"
        rpy="0 0 0" />
      <geometry>
        <mesh
          filename="package://WholeUrdfV7_1/meshes/DriWheel_L.STL" />
      </geometry>
      <material
        name="">
        <color
          rgba="0.75294 0.75294 0.75294 1" />
      </material>
    </visual>
    <collision>
      <origin
        xyz="0 0 0"
        rpy="0 0 0" />
      <geometry>
        <mesh
          filename="package://WholeUrdfV7_1/meshes/DriWheel_L.STL" />
      </geometry>
    </collision>
  </link>
  <joint
    name="JT_DriWheel_L"
    type="continuous">
    <origin
      xyz="0 0.1719 0.056"
      rpy="0 0 0" />
    <parent
      link="Base_link" />
    <child
      link="DriWheel_L" />
    <axis
      xyz="0 1 0" />
    <limit
      lower="0"
      upper="0"
      effort="0"
      velocity="0" />
  </joint>
</robot>
